Workbook

Sheet 종합
A1: 구분 | ES1: i
C2: 데이터 | I2: 수식 | N2: 데이터 | T2: 수식 | Y2: 데이터 / 수식 | AD2: 수식 | AJ2: 수식 | AU2: 이음 계산 | AV2: 데이터 | BB2: 수식 | BG2: 데이터 | BL2: 수식 | BQ2: 수식 | BR2: 데이터 | BW2: 수식 | BX2: 수식 | BY2: 데이터 | CC2: 수식 | CF2: 데이터 | CI2: 데이터 | CL2: 데이터 | CO2: 수식 | CR2: 고정값 | CU2: 수식 | CX2: 수식 | CY2: 데이터 | DB2: 데이터 | DF2: 데이터 | DI2: 데이터 | DL2: 데이터 | DU2: 데이터 | DX2: 고정값 | EA2: 수식 | ED2: 수식 | EE2: 수식 | EF2: 수식 | EG2: 데이터 | EH2: 데이터 | EJ2: 수식 | EK2: 데이터 | EL2: 데이터 | EO2: 수식 | EP2: 데이터 | EQ2: 데이터 | ES2: 수식 | ET2: 데이터 | EU2: 데이터 | EX2: 수식 | EY2: 수식 | FB2: 수식 | FC2: 수식 | FF2: 수식 | FG2: 수식 | GC2: 데이터 | GD2: 수식 | GG2: 데이터 | GH2: 수식 | GI2: 수식 | GJ2: 데이터 | GK2: 데이터 | GL2: 데이터 | GM2: 데이터 | GN2: 수식 | GO2: 데이터 | GP2: 수식 | GQ2: 수식 | GR2: 데이터 | GS2: 수식 | GT2: 결과
C3: 업데이트 : 연간 단위, 매년 2월 데이터 업데이트 통계청 주택총조사(거처의 종류, 일반, 외국인가구, 전체) 6년 데이터 필요 | I3: 전년대비 일반가구 증감수 5년 데이터 필요 | N3: 업데이트 : 연간 단위, 매년 2월 데이터 업데이트 통계청 인구총조사(가구, 1인가구) 6년 데이터 필요 | T3: 전년대비 1인가구 증감수 5년 데이터 필요 | Y3: 업데이트 : 연간 단위, 매년 2월 데이터 업데이트 통계청 주택총조사(거처의 종류, 일반, 외국인가구, 아파트) 5년 데이터 필요, 아파트/전체(%) | AD3: 일반가구 증가수에 일반아파트 가구증가 비율을 *하여 산출 (동일 년도) 5년치 평균값을 구함 | AJ3: 1인가구 증가수에 일반아파트 가구증가 비율을 *하여 산출 (동일 년도) 5년치 평균값을 구함 | AP3: 소계는 일반아파트가구증가_최근5년평균과 동일 | AU3: 소계의 5개년 평균값 | AV3: 업데이트 : 연간 단위, 매년 2월 데이터 업데이트 통계청 주택총조사(거처의 종류, 일반, 외국인가구, 전체) 6년 데이터 필요 | BB3: 전년대비 외국인가구 증감수 5년 데이터 필요 | BG3: 업데이트 : 연간 단위, 매년 2월 데이터 업데이트 통계청 주택총조사(거처의 종류, 일반, 외국인가구, 아파트) 5년치 데이터 필요, 외국인 아파트/외국인(%) | BL3: 외국인가구 증가수에 외국인아파트 가구 비율을 *하여 산출 (동일 년도) 5년치 평균값을 구함 | BR3: 업데이트 : 연간 단위, 매년 2월에 데이터 업데이트 REPS의 시도 단위 멸실 아파트 데이터 활용 5년치 데이터 필요 | BW3: 멸실 5년 평균 | BX3: 일반아파트 가구증가 5년 평균 + 외국인아파트 가구증가 5년 평균 + 시군구 멸실 아파트 5년 평균 | BY3: 업데이트 : 연간 단위, 매년 2월에 데이터 업데이트 통계청 주택소유통계(다주택자) 4년 데이터 필요 | CC3: 전년대비 다주택자 증감수 3년 데이터 필요 | CF3: 업데이트 : 연간 단위, 매년 2월에 데이터 업데이트 REPS 거래량통계(시군구내/전체) 3년 데이터 필요 | CI3: 업데이트 : 분기 단위(1년4회) EX)25.2월 = 24.1Q ~ 24.4Q 데이터 EX)25.5월 = 24.2Q ~ 25.1Q 데이터 REPS 단위당가격(평당가) | CL3: 업데이트 : 분기 단위(1년4회) EX)25.2월 = 24.1Q ~ 24.4Q 데이터 EX)25.5월 = 24.2Q ~ 25.1Q 데이터 REPS 분양가(평당가) | CO3: 매매평균실거래/평균분양가(%) | CR3: 3년 가중치 고정 20% / 30% / 50% | CU3: 다주택자증가*내지인거래비율* 가격보정(실거래/분양가)*3년 가중치 각 년도의 값에 맞게 계산 | CX3: 내부투자수요 3년치 평균 | CY3: 업데이트 : 연간 단위, 매년 2월에 데이터 업데이트 REPS 미분양통계 3년 데이터 필요 | DB3: 업데이트 : 연간 단위, 매년 2월에 데이터 업데이트 REPS 미분양통계 4년 데이터 필요 | DF3: 업데이트 : 연간 단위, EX)2024년 분양물량+2023년 미분양물량 | DI3: 업데이트 : 연간 단위, 2024(분양물량+전년미분양) - 2024미분양물량 | DL3: 내부투자수요와 동일한 기준 | DU3: 업데이트 : 연간 단위, 매년 2월에 데이터 업데이트 REPS 미분양통계 4년 데이터 필요 | DX3: 3년 가중치 고정값 20% / 30% / 50% | EA3: 소화물량*외지인거래비율* 가격보정(실거래/분양가)*3년 가중치 각 년도의 값에 맞게 계산 | ED3: 외부투자수요 3년치 평균 | EE3: 내부투자수요3년치 평균+외부투자수요3년치 평균 | EF3: 자연발생수요(BX) + 투자수요(EE) | EG3: 업데이트 : 연간 단위 매년 2월에 데이터 업데이트 REPS 실거래 단위당가격 | EH3: 투자수요의 직전분양가 활용 | EJ3: 직전분양가의 55% EI*0.55 | EK3: 업데이트 : 분기 단위(1년4회) 각 지역별 평균분양가의 55%가 넘는 세대의 총합 전용 110이하, 매매가 | EL3: 소득분위 계산값 활용 FZ | EM3: 고정값 | EN3: 고정값 | EO3: 기준가격이상세대수(EK) * 소득분위(EL) * 자가거주비율(EM) * 이사계획(EN) | EP3: =EG | EQ3: 투자수요의 직전분양가 활용 | ES3: 직전분양가의 55% ER*0.55 | ET3: 업데이트 : 분기 단위(1년4회) 각 지역별 평균분양가의 55%가 넘는 세대의 총합 전용 110이하, 전세가 | EU3: 소득분위 계산값 활용 FZ | EV3: 고정값 | EW3: 고정값 | EX3: 기준가격이상세대수(ET) * 소득분위(EU) * 자가거주비율(EV) * 이사계획(EW) | EY3: 주택총조사 주택의 종류 데이터로 작업 | FB3: (EZ+FA) /EY | FC3: (EO+EX) *FB | FD3: 고정값 | FE3: 고정값 | FF3: FC*FD *FE | FG3: EO+EX +FF | FH3: 데이터솔루션UNIT에서 작업 후 전달 1년 1회 업데이트, 매년 2월 | GA3: 고정값 | GB3: 고정값 | GC3: 소득분위 계산값 활용 FZ | GD3: GA*GB *GC | GE3: 고정값 | GF3: 고정값 | GG3: 소득분위 계산값 활용 FZ | GH3: GE*GF *GG | GI3: GD+GH | GJ3: =CX | GK3: =ED | GL3: 업데이트 : 연간 단위, 매년 2월 데이터 업데이트 통계청 주택총조사(주택의종류) 아파트+연립+다세대주택 | GM3: 전년도 미분양 데이터 | GN3: GM/GL | GO3: 미분양관리지역활용 분기별 업데이트 | GP3: (GJ+GK) /GO | GQ3: FG+GI+GP | GR3: 당해년 포함 최근 3개년 물량 합/3 (예정물량 포함) | GS3: 공급물량GR/ 유효수요GQ | GT3: 수급 등급 결과값
CL7: 분양가가 3개년 없는 경우 모두 0 처리 분양가가 3개년 모두 있는 경우 그대로 활용 분양가가 1or2개년 있는 경우 *5%로 분양가 생성 ex)1,312/0/0일경우 1,312/1,312*1.05/(1,312*1.05)*1.05
C11: 수요
C12: 자연발생수요(a) | BY12: 투자수요 | EF12: 신규수요 | EG12: 유효수요 | GQ12: 유효수요 | GR12: 공급물량(예정포함) | GS12: 공급물량 대비 유효수요 (공급물량/유효수요) | GT12: 수급 등급 공급물량/APT유효수요 S등급 : 50% 이하 A등급 : 50%초과 100%이하 B등급 : 100%초과 150%이하 C등급 : 150%초과 | GV12: 등급 기준
A13: 권역 | B13: 지역 | C13: 일반가구아파트수요 | AV13: 외국인가구아파트수요 | BX13: 자연발생수요(계) | BY13: 내부투자수요 | CY13: 외부투자수요 | EE13: 투자수요 소계 | EG13: 자가가구아파트이주수요 | EP13: 임차가구아파트 이주수요 | EY13: 비아파트이주수요 | FG13: 이주수요 계 | FH13: 소득분위 계산 | GA13: 1인&외국인가구 증가, 유효수요 | GE13: 1인 外&멸실가구 증가, 유효수요 | GI13: 가구증가 수요 계 | GJ13: 투자수요 | GL13: 미분양 수준 보정 | GP13: 투자수요 계
A14: 권역 | B14: 지역 | C14: 일반가구수(통계청 주택총조사_일반,외국인가구) | I14: 일반가구증가(1인가구 外 전년대비 증감수) | N14: 1인가구수(인구총조사_1인가구) | T14: 1인가구증가 | Y14: 일반가구아파트비율 | AD14: 일반아파트가구증가(1인가구 外_최근5년평균 | AJ14: 1인아파트가구증가_최근5년평균 | AP14: 소계(a) | AU14: 결과_최근5개년소계평균 | AV14: 외국인가구수(주택총조사_일반,외국인가구) | BB14: 외국인가구증가 | BG14: 외국인가구아파트비율 | BL14: 외국인아파트가구증가 | BQ14: 외국인아파트가구증가_최근5개년평균(b) | BR14: 시도 멸실 아파트 | BW14: 시군구별멸실아파트 5년 평균© | BX14: a+b+c | BY14: 다주택자 | CC14: 다주택자증가(전년대비) | CF14: 내지인거래비율 | CI14: 매매평균실거래 | CL14: 평균분양가 | CO14: 가격보정(실거래/분양가) | CR14: 3년 가중치 | CU14: 투자수요(내부) 소계_a | CX14: 평균(결과) | CY14: 분양물량 | DB14: 연말 기준 미분양물량 | DF14: 분양물량+전년미분양 | DI14: 소화물량 | DL14: 매매평균실거래 | DO14: 평균분양가 | DR14: 가격보정(실거래/분양가) | DU14: 외지인거래비율 | DX14: 3년 가중치 | EA14: 투자수요(외부) 소계_b | ED14: 평균(결과) | EE14: a+b | EF14: 자연발생수요+투자수요 | EG14: 직전년 평균평단가 | EH14: 직전년 평균분양가 | EJ14: 직전년 평균분양가의 55% | EK14: 기준가격 이상 apt 세대수(매매가) | EL14: 소득분위 | EM14: 자가거주비율 | EN14: 이사계획 有 | EO14: 자가가구 apt 이주 수요 | EP14: 직전년 평균평단가 | EQ14: 직전년 평균분양가 | ES14: 직전년 평균분양가의 55% | ET14: 기준가격 이상 apt 세대수(전세가) | EU14: 소득분위 | EV14: 임차비율 | EW14: 이사계획 有 | EX14: 임차가구apt 이주 수요 | EY14: 아파트 가구 비율 | EZ14: 단독 가구 비율 | FA14: 연립다세대 가구 비율 | FB14: (단독+다세대/아파트)가구 비율 | FC14: 모수 보정 | FD14: 이사계획 보정 | FE14: 가격 보정 | FF14: 비apt 이주 수요 | FG14: 계 | FH14: 금리 | FI14: 상환기간(년) | FJ14: LTV | FK14: DTI | FL14: 평균 분양가(34평 기준, 직전년 평균 분양가*34) | FM14: 대출 수준 | FN14: 월상환금액(만원) | FO14: 연소득금액(만원) | FP14: 1500~2000만원미만 | FQ14: 2000~2500만원미만 | FR14: 2500~3000만원미만 | FS14: 3000~4000만원미만 | FT14: 4000~5000만원미만 | FU14: 5000~6000만원미만 | FV14: 6000~7000만원미만 | FW14: 7000만원~1억미만 | FX14: 1억이상 | FY14: 계 | FZ14: 소득 분위 | GA14: 1인&외국인가구 증가분 | GB14: 자가점유율 | GC14: 소득분위 | GD14: 결과 | GE14: 1인 外&멸실가구 증가분 | GF14: 자가점유율 | GG14: 소득분위 | GH14: 결과 | GI14: 계 | GJ14: 투자수요내부 | GK14: 투자수요외부 | GL14: 지역 제고 아파트수(아파트+연립+다세대) | GM14: 미분양 | GN14: 미분양 수준 | GO14: 결과 | GP14: 결과 | GQ14: 유효수요 계 (이전수요+가구증가수요+투자수요)
A15: 시점 | C15: 2018 | D15: 2019 | E15: 2020 | F15: 2021 | G15: 2022 | H15: 2023 | I15: 2019 | J15: 2020 | K15: 2021 | L15: 2022 | M15: 2023 | N15: 2018 | O15: 2019 | P15: 2020 | Q15: 2021 | R15: 2022 | S15: 2023 | T15: 2019 | U15: 2020 | V15: 2021 | W15: 2022 | X15: 2023 | Y15: 2019 | Z15: 2020 | AA15: 2021 | AB15: 2022 | AC15: 2023 | AD15: 2019 | AE15: 2020 | AF15: 2021 | AG15: 2022 | AH15: 2023 | AI15: 평균 | AJ15: 2019 | AK15: 2020 | AL15: 2021 | AM15: 2022 | AN15: 2023 | AO15: 평균 | AP15: 2019 | AQ15: 2020 | AR15: 2021 | AS15: 2022 | AT15: 2023 | AV15: 2018 | AW15: 2019 | AX15: 2020 | AY15: 2021 | AZ15: 2022 | BA15: 2023 | BB15: 2019 | BC15: 2020 | BD15: 2021 | BE15: 2022 | BF15: 2023 | BG15: 2019 | BH15: 2020 | BI15: 2021 | BJ15: 2022 | BK15: 2023 | BL15: 2019 | BM15: 2020 | BN15: 2021 | BO15: 2022 | BP15: 2023 | BR15: 2020 | BS15: 2021 | BT15: 2022 | BU15: 2023 | BV15: 2024 | BY15: 2020 | BZ15: 2021 | CA15: 2022 | CB15: 2023 | CC15: 2021 | CD15: 2022 | CE15: 2023 | CF15: 2022 | CG15: 2023 | CH15: 2024 | CI15: 2022 | CJ15: 2023 | CK15: 2024 | CL15: 2022 | CM15: 2023 | CN15: 2024 | CO15: 2022 | CP15: 2023 | CQ15: 2024 | CR15: 2022 | CS15: 2023 | CT15: 2024 | CU15: 2022 | CV15: 2023 | CW15: 2024 | CY15: 2022 | CZ15: 2023 | DA15: 2024 | DB15: 2021 | DC15: 2022 | DD15: 2023 | DE15: 2024 | DF15: 2022 | DG15: 2023 | DH15: 2024 | DI15: 2022 | DJ15: 2023 | DK15: 2024 | DL15: 2022 | DM15: 2023 | DN15: 2024 | DO15: 2022 | DP15: 2023 | DQ15: 2024 | DR15: 2022 | DS15: 2023 | DT15: 2024 | DU15: 2022 | DV15: 2023 | DW15: 2024 | DX15: 2022 | DY15: 2023 | DZ15: 2024 | EA15: 2022 | EB15: 2023 | EC15: 2024 | ED15: 평균(결과) | EE15: 계 | EF15: 계 | EG15: 2024 | EH15: 2024 | EI15: 2024 | EJ15: 2024 | EK15: 2025 | EP15: 2024 | EQ15: 2024 | ER15: 2024 | ES15: 2024 | ET15: 2025 | GR15: 2023~25
A16: 강원도 | B16: 강원도 | C16: ='주택총조사(거처의종류, 일반,외국인가구, 전체)'!H3 -> 628484 | D16: ='주택총조사(거처의종류, 일반,외국인가구, 전체)'!K3 -> 633942 | E16: ='주택총조사(거처의종류, 일반,외국인가구, 전체)'!N3 -> 661039 | F16: ='주택총조사(거처의종류, 일반,외국인가구, 전체)'!Q3 -> 674728 | G16: ='주택총조사(거처의종류, 일반,외국인가구, 전체)'!T3 -> 684895 | H16: ='주택총조사(거처의종류, 일반,외국인가구, 전체)'!W3 -> 698410 | I16: =D16-C16-T16 -> 2896 | J16: =E16-D16-U16 -> 4583 | K16: =F16-E16-V16 -> 48 | L16: =G16-F16-W16 -> 738 | M16: =H16-G16-X16 -> -3141 | N16: ='인구총조사(가구, 1인가구)'!D3 -> 206295 | O16: ='인구총조사(가구, 1인가구)'!E3 -> 208857 | P16: ='인구총조사(가구, 1인가구)'!F3 -> 231371 | Q16: ='인구총조사(가구, 1인가구)'!G3 -> 245012 | R16: ='인구총조사(가구, 1인가구)'!H3 -> 254441 | S16: ='인구총조사(가구, 1인가구)'!I3 -> 271097 | T16: =O16-N16 -> 2562 | U16: =P16-O16 -> 22514 | V16: =Q16-P16 -> 13641 | W16: =R16-Q16 -> 9429 | X16: =S16-R16 -> 16656 | Y16: ='주택총조사(거처의종류, 일반,외국인가구, 아파트)'!K3/'주택총조사(거처의종류, 일반,외국인가구, 전체)'!K3 -> 0.46242243 | Z16: ='주택총조사(거처의종류, 일반,외국인가구, 아파트)'!N3/'주택총조사(거처의종류, 일반,외국인가구, 전체)'!N3 -> 0.46664418 | AA16: ='주택총조사(거처의종류, 일반,외국인가구, 아파트)'!Q3/'주택총조사(거처의종류, 일반,외국인가구, 전체)'!Q3 -> 0.47587324 | AB16: ='주택총조사(거처의종류, 일반,외국인가구, 아파트)'!T3/'주택총조사(거처의종류, 일반,외국인가구, 전체)'!T3 -> 0.48313099 | AC16: ='주택총조사(거처의종류, 일반,외국인가구, 아파트)'!W3/'주택총조사(거처의종류, 일반,외국인가구, 전체)'!W3 -> 0.48151229 | AD16: =I16*Y16 -> 1339.1754 | AE16: =J16*Z16 -> 2138.6303 | AF16: =K16*AA16 -> 22.841916 | AG16: =L16*AB16 -> 356.55067 | AH16: =M16*AC16 -> -1512.4301 | AI16: =AVERAGE(AD16:AH16) -> 468.95362 | AJ16: =T16*Y16 -> 1184.7263 | AK16: =U16*Z16 -> 10506.027 | AL16: =V16*AA16 -> 6491.3869 | AM16: =W16*AB16 -> 4555.4421 | AN16: =X16*AC16 -> 8020.0687 | AO16: =AVERAGE(AJ16:AN16) -> 6151.5302 | AP16: =AD16+AJ16 -> 2523.9016 | AQ16: =AE16+AK16 -> 12644.657 | AR16: =AF16+AL16 -> 6514.2288 | AS16: =AG16+AM16 -> 4911.9928 | AT16: =AH16+AN16 -> 6507.6386 | AU16: =AVERAGE(AP16:AT16) -> 6620.4838 | AV16: ='주택총조사(거처의종류, 일반,외국인가구, 전체)'!I3 -> 5692 | AW16: ='주택총조사(거처의종류, 일반,외국인가구, 전체)'!L3 -> 6442 | AX16: ='주택총조사(거처의종류, 일반,외국인가구, 전체)'!O3 -> 6845 | AY16: ='주택총조사(거처의종류, 일반,외국인가구, 전체)'!R3 -> 7242 | AZ16: ='주택총조사(거처의종류, 일반,외국인가구, 전체)'!U3 -> 8010 | BA16: ='주택총조사(거처의종류, 일반,외국인가구, 전체)'!X3 -> 9831 | BB16: =AW16-AV16 -> 750 | BC16: =AX16-AW16 -> 403 | BD16: =AY16-AX16 -> 397 | BE16: =AZ16-AY16 -> 768 | BF16: =BA16-AZ16 -> 1821 | BG16: ='주택총조사(거처의종류, 일반,외국인가구, 아파트)'!L3/'주택총조사(거처의종류, 일반,외국인가구, 전체)'!L3 -> 0.16299286 | BH16: ='주택총조사(거처의종류, 일반,외국인가구, 아파트)'!O3/'주택총조사(거처의종류, 일반,외국인가구, 전체)'!O3 -> 0.17005113 | BI16: ='주택총조사(거처의종류, 일반,외국인가구, 아파트)'!R3/'주택총조사(거처의종류, 일반,외국인가구, 전체)'!R3 -> 0.16238608 | BJ16: ='주택총조사(거처의종류, 일반,외국인가구, 아파트)'!U3/'주택총조사(거처의종류, 일반,외국인가구, 전체)'!U3 -> 0.16541823 | BK16: ='주택총조사(거처의종류, 일반,외국인가구, 아파트)'!X3/'주택총조사(거처의종류, 일반,외국인가구, 전체)'!X3 -> 0.14657715 | BL16: =BB16*BG16 -> 122.24464 | BM16: =BC16*BH16 -> 68.530606 | BN16: =BD16*BI16 -> 64.467274 | BO16: =BE16*BJ16 -> 127.0412 | BP16: =BF16*BK16 -> 266.917 | BQ16: =AVERAGE(BL16:BP16) -> 129.84014 | BR16: =REPS멸실!E2 -> 0 | BS16: =REPS멸실!F2 -> 0 | BT16: =REPS멸실!G2 -> 0 | BU16: =REPS멸실!H2 -> 0 | BV16: =REPS멸실!I2 -> 42 | BW16: =AVERAGE(BR16:BV16) -> 8.4 | BX16: =SUM(AU16,BQ16,BW16) -> 6758.724 | BY16: =SUM('주택소유통계(다주택자)'!Q3:R3) -> 78461 | BZ16: =SUM('주택소유통계(다주택자)'!U3:V3) -> 78262 | CA16: =SUM('주택소유통계(다주택자)'!Y3:Z3) -> 80478 | CB16: =SUM('주택소유통계(다주택자)'!AC3:AD3) -> 84018 | CC16: =BZ16-BY16 -> -199 | CD16: =CA16-BZ16 -> 2216 | CE16: =CB16-CA16 -> 3540 | CF16: ='REPS거래량(외지인)'!D3/'REPS거래량(외지인)'!C3 -> 0.52451816 | CG16: ='REPS거래량(외지인)'!I3/'REPS거래량(외지인)'!H3 -> 0.58317333 | CH16: ='REPS거래량(외지인)'!N3/'REPS거래량(외지인)'!M3 -> 0.70846301 | CI16: =REPS단위당실거래!G2 -> 748.8 | CJ16: =REPS단위당실거래!H2 -> 749.4 | CK16: =REPS단위당실거래!I2 -> 755.1 | CL16: 1312 | CM16: 1546 | CN16: 1377 | CO16: =CI16/CL16 -> 0.57073171 | CP16: =CJ16/CM16 -> 0.4847348 | CQ16: =CK16/CN16 -> 0.54836601 | CR16: 0.2 | CS16: 0.3 | CT16: 0.5 | CU16: =CC16*CF16*CO16*CR16 -> -11.914494 | CV16: =CD16*CG16*CP16*CS16 -> 187.92859 | CW16: =CE16*CH16*CQ16*CT16 -> 687.63976 | CX16: =AVERAGE(CU16:CW16) -> 287.88462 | CY16: =REPS분양물량!H2 -> 10209 | CZ16: =REPS분양물량!I2 -> 8522 | DA16: =REPS분양물량!J2 -> 2278 | DB16: =REPS미분양!F2 -> 1648 | DC16: =REPS미분양!G2 -> 2648 | DD16: =REPS미분양!H2 -> 4001 | DE16: =REPS미분양!I2 -> 4408 | DF16: =SUM(CY16,DB16) -> 11857 | DG16: =SUM(CZ16,DC16) -> 11170 | DH16: =SUM(DA16,DD16) -> 6279 | DI16: =DF16-DC16 -> 9209 | DJ16: =DG16-DD16 -> 7169 | DK16: =DH16-DE16 -> 1871 | DL16: 748.8 | DM16: 749.4 | DN16: 755.1 | DO16: ='REPS분양가(분기단위)'!D2 -> 1312 | DP16: ='REPS분양가(분기단위)'!E2 -> 1546 | DQ16: ='REPS분양가(분기단위)'!F2 -> 1377 | DR16: =DL16/DO16 -> 0.57073171 | DS16: =DM16/DP16 -> 0.4847348 | DT16: =DN16/DQ16 -> 0.54836601 | DU16: =100%-종합!CF16 -> 0.47548184 | DV16: =100%-종합!CG16 -> 0.41682667 | DW16: =100%-종합!CH16 -> 0.29153699 | DX16: 0.2 | DY16: 0.3 | DZ16: 0.5 | EA16: =DI16*DR16*DU16*DX16 -> 499.81399 | EB16: =DJ16*DS16*DV16*DY16 -> 434.54978 | EC16: =DK16*DT16*DW16*DZ16 -> 149.55743 | ED16: =AVERAGE(EA16:EC16) -> 361.30706 | EE16: =CX16+ED16 -> 649.19168 | EF16: =BX16+EE16 -> 7407.9156 | EG16: =REPS단위당실거래!I2 -> 755.1 | EH16: =DQ16 -> 1377 | EI16: =ROUND(EH16*34,-2) -> 46800 | EJ16: =EI16*0.55 -> 25740 | EK16: 101227 | EL16: =FZ16 -> 0.67572783 | EM16: 0.74 | EN16: 0.05 | EO16: =EK16*EL16*EM16*EN16 -> 2530.8703 | EP16: =REPS단위당실거래!I2 -> 755.1 | EQ16: =DQ16 -> 1377 | ER16: =ROUND(EQ16*34,-2) -> 46800 | ES16: =ER16*0.55 -> 25740 | ET16: 40896 | EU16: =FZ16 -> 0.67572783 | EV16: 0.26 | EW16: 0.2 | EX16: =ET16*EU16*EV16*EW16 -> 1436.9974 | EY16: ='주택총조사(주택의종류)'!AZ3 -> 0.55656803 | EZ16: ='주택총조사(주택의종류)'!AS3 -> 0.37228418 | FA16: ='주택총조사(주택의종류)'!BG3 -> 0.053263771 | FB16: =SUM(EZ16:FA16)/EY16 -> 0.76459288 | FC16: =SUM(EO16,EX16)*FB16 -> 3033.8034 | FD16: 0.4 | FE16: 0.6 | FF16: =FC16*FD16*FE16 -> 728.11281 | FG16: =SUM(EO16,EX16,FF16) -> 4695.9805 | FH16: 0.0394 | FI16: 30 | FJ16: 0.6 | FK16: 0.4 | FL16: =ROUND(EH16*34,-3) -> 47000 | FM16: =ROUND(EH16*34*FJ16,-2) -> 28100 | FN16: =PMT(FH16/12,FI16*12,FM16) -> -133.18352 | FO16: =-ROUND(FN16/FK16,-1)*12 -> 3960 | FP16: 1371 | FQ16: 4323 | FR16: 37385 | FS16: 56409 | FT16: 32707 | FU16: 29152 | FV16: 27787 | FW16: 62951 | FX16: 54719 | FY16: =SUM(FP16:FX16) -> 306804 | FZ16: =(SUM(FT16:FX16)/FY16) -> 0.67572783 | GA16: =SUM(AO16,BQ16) -> 6281.3703 | GB16: 0.3 | GC16: =FZ16 -> 0.67572783 | GD16: =GA16*GB16*GC16 -> 1273.349 | GE16: =SUM(AI16,BW16) -> 477.35362 | GF16: 0.7 | GG16: =FZ16 -> 0.67572783 | GH16: =GE16*GF16*GG16 -> 225.79279 | GI16: =GD16+GH16 -> 1499.1418 | GJ16: =CX16 -> 287.88462 | GK16: =ED16 -> 361.30706 | GL16: =SUM('주택총조사(주택의종류)'!AD3:AF3) -> 414188 | GM16: =REPS미분양!I2 -> 4408 | GN16: =GM16/GL16 -> 0.01064251 | GO16: =LOOKUP(GN16,$GW$25:$GX$28) -> 0.6 | GP16: =SUM(GJ16:GK16)*GO16 -> 389.51501 | GQ16: =SUM(FG16,GI16,GP16) -> 6584.6373 | GR16: =SUM('REPS분양물량+계획'!G2:I2)/3 -> 5499 | GS16: =GR16/GQ16 -> 0.83512572 | GT16: =LOOKUP(GS16,$GW$16:$GX$20) -> A등급 | GV16: 50%이하 | GW16: 0 | GX16: S등급
A17: 강원도 | B17: 강릉시 | C17: 92093 | D17: 98032 | E17: 99105 | F17: 97663 | G17: 98918 | H17: 98987 | I17: =D17-C17-T17 -> 423 | J17: =E17-D17-U17 -> 127 | K17: =F17-E17-V17 -> -346 | L17: =G17-F17-W17 -> -609 | M17: =H17-G17-X17 -> -378 | N17: 32119 | O17: 37635 | P17: 38581 | Q17: 37485 | R17: 39349 | S17: 39796 | T17: =O17-N17 -> 5516 | U17: =P17-O17 -> 946 | V17: =Q17-P17 -> -1096 | W17: =R17-Q17 -> 1864 | X17: =S17-R17 -> 447 | Y17: 0.46 | Z17: 0.47 | AA17: 0.49 | AB17: 0.49 | AC17: 0.5 | AD17: =I17*Y17 -> 194.58 | AE17: =J17*Z17 -> 59.69 | AF17: =K17*AA17 -> -169.54 | AG17: =L17*AB17 -> -298.41 | AH17: =M17*AC17 -> -189 | AI17: =AVERAGE(AD17:AH17) -> -80.536 | AJ17: =T17*Y17 -> 2537.36 | AK17: =U17*Z17 -> 444.62 | AL17: =V17*AA17 -> -537.04 | AM17: =W17*AB17 -> 913.36 | AN17: =X17*AC17 -> 223.5 | AO17: =AVERAGE(AJ17:AN17) -> 716.36 | AP17: =AD17+AJ17 -> 2731.94 | AQ17: =AE17+AK17 -> 504.31 | AR17: =AF17+AL17 -> -706.58 | AS17: =AG17+AM17 -> 614.95 | AT17: =AH17+AN17 -> 34.5 | AU17: =AVERAGE(AP17:AT17) -> 635.824 | AV17: 880 | AW17: 994 | AX17: 1120 | AY17: 1222 | AZ17: 1552 | BA17: 1818 | BB17: =AW17-AV17 -> 114 | BC17: =AX17-AW17 -> 126 | BD17: =AY17-AX17 -> 102 | BE17: =AZ17-AY17 -> 330 | BF17: =BA17-AZ17 -> 266 | BG17: 0.13 | BH17: 0.12 | BI17: 0.12 | BJ17: 0.1 | BK17: 0.09 | BL17: =BB17*BG17 -> 14.82 | BM17: =BC17*BH17 -> 15.12 | BN17: =BD17*BI17 -> 12.24 | BO17: =BE17*BJ17 -> 33 | BP17: =BF17*BK17 -> 23.94 | BQ17: =AVERAGE(BL17:BP17) -> 19.824 | BR17: 0 | BS17: 0 | BT17: 0 | BU17: 0 | BV17: 0 | BW17: =AVERAGE(BR17:BV17) -> 0 | BX17: =SUM(AU17,BQ17,BW17) -> 655.648 | BY17: =SUM('주택소유통계(다주택자)'!Q3:R3) -> 78461 | BZ17: =SUM('주택소유통계(다주택자)'!U3:V3) -> 78262 | CA17: =SUM('주택소유통계(다주택자)'!Y3:Z3) -> 80478 | CB17: =SUM('주택소유통계(다주택자)'!AC3:AD3) -> 84018 | CC17: =BZ17-BY17 -> -199 | CD17: =CA17-BZ17 -> 2216 | CE17: =CB17-CA17 -> 3540 | CF17: ='REPS거래량(외지인)'!D3/'REPS거래량(외지인)'!C3 -> 0.52451816 | CG17: ='REPS거래량(외지인)'!I3/'REPS거래량(외지인)'!H3 -> 0.58317333 | CH17: ='REPS거래량(외지인)'!N3/'REPS거래량(외지인)'!M3 -> 0.70846301 | CI17: =REPS단위당실거래!G2 -> 748.8 | CJ17: =REPS단위당실거래!H2 -> 749.4 | CK17: =REPS단위당실거래!I2 -> 755.1 | CL17: 1461 | CM17: 1671 | CN17: 1498 | CO17: =CI17/CL17 -> 0.51252567 | CP17: =CJ17/CM17 -> 0.44847397 | CQ17: =CK17/CN17 -> 0.5040721 | CR17: 0.2 | CS17: 0.3 | CT17: 0.5 | CU17: =CC17*CF17*CO17*CR17 -> -10.699395 | CV17: =CD17*CG17*CP17*CS17 -> 173.8705 | CW17: =CE17*CH17*CQ17*CT17 -> 632.09609 | CX17: =AVERAGE(CU17:CW17) -> 265.08907 | CY17: =REPS분양물량!H2 -> 10209 | CZ17: =REPS분양물량!I2 -> 8522 | DA17: =REPS분양물량!J2 -> 2278 | DB17: =REPS미분양!F2 -> 1648 | DC17: =REPS미분양!G2 -> 2648 | DD17: =REPS미분양!H2 -> 4001 | DE17: =REPS미분양!I2 -> 4408 | DF17: =SUM(CY17,DB17) -> 11857 | DG17: =SUM(CZ17,DC17) -> 11170 | DH17: =SUM(DA17,DD17) -> 6279 | DI17: =DF17-DC17 -> 9209 | DJ17: =DG17-DD17 -> 7169 | DK17: =DH17-DE17 -> 1871 | DL17: 908.3 | DM17: 845.7 | DN17: 809.4 | DO17: ='REPS분양가(분기단위)'!D2 -> 1312 | DP17: ='REPS분양가(분기단위)'!E2 -> 1546 | DQ17: ='REPS분양가(분기단위)'!F2 -> 1377 | DR17: =DL17/DO17 -> 0.69230183 | DS17: =DM17/DP17 -> 0.54702458 | DT17: =DN17/DQ17 -> 0.58779956 | DU17: =100%-종합!CF17 -> 0.47548184 | DV17: =100%-종합!CG17 -> 0.41682667 | DW17: =100%-종합!CH17 -> 0.29153699 | DX17: 0.2 | DY17: 0.3 | DZ17: 0.5 | EA17: =DI17*DR17*DU17*DX17 -> 606.2781 | EB17: =DJ17*DS17*DV17*DY17 -> 490.39064 | EC17: =DK17*DT17*DW17*DZ17 -> 160.31225 | ED17: =AVERAGE(EA17:EC17) -> 418.99367 | EE17: =CX17+ED17 -> 684.08273 | EF17: =BX17+EE17 -> 1339.7307 | EG17: =REPS단위당실거래!I2 -> 755.1 | EH17: =DQ17 -> 1377 | EI17: =ROUND(EH17*34,-2) -> 46800 | EJ17: =EI17*0.55 -> 25740 | EK17: 13085 | EL17: =FZ17 -> 0.63743408 | EM17: 0.74 | EN17: 0.05 | EO17: =EK17*EL17*EM17*EN17 -> 308.61052 | EP17: =REPS단위당실거래!I2 -> 755.1 | EQ17: =DQ17 -> 1377 | ER17: =ROUND(EQ17*34,-2) -> 46800 | ES17: =ER17*0.55 -> 25740 | ET17: 4067 | EU17: =FZ17 -> 0.63743408 | EV17: 0.26 | EW17: 0.2 | EX17: =ET17*EU17*EV17*EW17 -> 134.80711 | EY17: ='주택총조사(주택의종류)'!AZ3 -> 0.55656803 | EZ17: ='주택총조사(주택의종류)'!AS3 -> 0.37228418 | FA17: ='주택총조사(주택의종류)'!BG3 -> 0.053263771 | FB17: =SUM(EZ17:FA17)/EY17 -> 0.76459288 | FC17: =SUM(EO17,EX17)*FB17 -> 339.03396 | FD17: 0.4 | FE17: 0.6 | FF17: =FC17*FD17*FE17 -> 81.36815 | FG17: =SUM(EO17,EX17,FF17) -> 524.78578 | FH17: 0.0394 | FI17: 30 | FJ17: 0.6 | FK17: 0.4 | FL17: =ROUND(EH17*34,-3) -> 47000 | FM17: =ROUND(EH17*34*FJ17,-2) -> 28100 | FN17: =PMT(FH17/12,FI17*12,FM17) -> -133.18352 | FO17: =-ROUND(FN17/FK17,-1)*12 -> 3960 | FP17: 177 | FQ17: 613 | FR17: 5794 | FS17: 8076 | FT17: 4526 | FU17: 4158 | FV17: 4055 | FW17: 8923 | FX17: 7857 | FY17: =SUM(FP17:FX17) -> 44179 | FZ17: =(SUM(FU17:FX17)/FY17)+(FT17/FY17)*0.7 -> 0.63743408 | GA17: =SUM(AO17,BQ17) -> 736.184 | GB17: 0.3 | GC17: =FZ17 -> 0.63743408 | GD17: =GA17*GB17*GC17 -> 140.78063 | GE17: =SUM(AI17,BW17) -> -80.536 | GF17: 0.7 | GG17: =FZ17 -> 0.63743408 | GH17: =GE17*GF17*GG17 -> -35.935473 | GI17: =GD17+GH17 -> 104.84516 | GJ17: =CX17 -> 265.08907 | GK17: =ED17 -> 418.99367 | GL17: =SUM('주택총조사(주택의종류)'!AD3:AF3) -> 414188 | GM17: =REPS미분양!I2 -> 4408 | GN17: =GM17/GL17 -> 0.01064251 | GO17: =LOOKUP(GN17,$GW$25:$GX$28) -> 0.6 | GP17: =SUM(GJ17:GK17)*GO17 -> 410.44964 | GQ17: =SUM(FG17,GI17,GP17) -> 1040.0806 | GR17: =SUM('REPS분양물량+계획'!G2:I2)/3 -> 5499 | GS17: =GR17/GQ17 -> 5.2870904 | GT17: =LOOKUP(GS17,$GW$16:$GX$20) -> C등급 | GV17: 50%초과~100%이하 | GW17: 0.501 | GX17: A등급
A18: 강원도 | B18: 강릉시 | C18: ='주택총조사(거처의종류, 일반,외국인가구, 전체)'!H4 -> 90664 | D18: ='주택총조사(거처의종류, 일반,외국인가구, 전체)'!K4 -> 92093 | E18: ='주택총조사(거처의종류, 일반,외국인가구, 전체)'!N4 -> 98032 | F18: ='주택총조사(거처의종류, 일반,외국인가구, 전체)'!Q4 -> 99105 | G18: ='주택총조사(거처의종류, 일반,외국인가구, 전체)'!T4 -> 97663 | H18: ='주택총조사(거처의종류, 일반,외국인가구, 전체)'!W4 -> 98918 | I18: =D18-C18-T18 -> 572 | J18: =E18-D18-U18 -> 423 | K18: =F18-E18-V18 -> 127 | L18: =G18-F18-W18 -> -346 | M18: =H18-G18-X18 -> -609 | N18: ='인구총조사(가구, 1인가구)'!D4 -> 31262 | O18: ='인구총조사(가구, 1인가구)'!E4 -> 32119 | P18: ='인구총조사(가구, 1인가구)'!F4 -> 37635 | Q18: ='인구총조사(가구, 1인가구)'!G4 -> 38581 | R18: ='인구총조사(가구, 1인가구)'!H4 -> 37485 | S18: ='인구총조사(가구, 1인가구)'!I4 -> 39349 | T18: =O18-N18 -> 857 | U18: =P18-O18 -> 5516 | V18: =Q18-P18 -> 946 | W18: =R18-Q18 -> -1096 | X18: =S18-R18 -> 1864 | Y18: ='주택총조사(거처의종류, 일반,외국인가구, 아파트)'!K4/'주택총조사(거처의종류, 일반,외국인가구, 전체)'!K4 -> 0.4757582 | Z18: ='주택총조사(거처의종류, 일반,외국인가구, 아파트)'!N4/'주택총조사(거처의종류, 일반,외국인가구, 전체)'!N4 -> 0.46234903 | AA18: ='주택총조사(거처의종류, 일반,외국인가구, 아파트)'!Q4/'주택총조사(거처의종류, 일반,외국인가구, 전체)'!Q4 -> 0.47486 | AB18: ='주택총조사(거처의종류, 일반,외국인가구, 아파트)'!T4/'주택총조사(거처의종류, 일반,외국인가구, 전체)'!T4 -> 0.48579298 | AC18: ='주택총조사(거처의종류, 일반,외국인가구, 아파트)'!W4/'주택총조사(거처의종류, 일반,외국인가구, 전체)'!W4 -> 0.4867466 | AD18: =I18*Y18 -> 272.13369 | AE18: =J18*Z18 -> 195.57364 | AF18: =K18*AA18 -> 60.30722 | AG18: =L18*AB18 -> -168.08437 | AH18: =M18*AC18 -> -296.42868 | AI18: =AVERAGE(AD18:AH18) -> 12.7003 | AJ18: =T18*Y18 -> 407.72478 | AK18: =U18*Z18 -> 2550.3172 | AL18: =V18*AA18 -> 449.21756 | AM18: =W18*AB18 -> -532.42911 | AN18: =X18*AC18 -> 907.29566 | AO18: =AVERAGE(AJ18:AN18) -> 756.42523 | AP18: =AD18+AJ18 -> 679.85847 | AQ18: =AE18+AK18 -> 2745.8909 | AR18: =AF18+AL18 -> 509.52478 | AS18: =AG18+AM18 -> -700.51348 | AT18: =AH18+AN18 -> 610.86698 | AU18: =AVERAGE(AP18:AT18) -> 769.12553 | AV18: ='주택총조사(거처의종류, 일반,외국인가구, 전체)'!I4 -> 598 | AW18: ='주택총조사(거처의종류, 일반,외국인가구, 전체)'!L4 -> 880 | AX18: ='주택총조사(거처의종류, 일반,외국인가구, 전체)'!O4 -> 994 | AY18: ='주택총조사(거처의종류, 일반,외국인가구, 전체)'!R4 -> 1120 | AZ18: ='주택총조사(거처의종류, 일반,외국인가구, 전체)'!U4 -> 1222 | BA18: ='주택총조사(거처의종류, 일반,외국인가구, 전체)'!X4 -> 1552 | BB18: =AW18-AV18 -> 282 | BC18: =AX18-AW18 -> 114 | BD18: =AY18-AX18 -> 126 | BE18: =AZ18-AY18 -> 102 | BF18: =BA18-AZ18 -> 330 | BG18: ='주택총조사(거처의종류, 일반,외국인가구, 아파트)'!L4/'주택총조사(거처의종류, 일반,외국인가구, 전체)'!L4 -> 0.13522727 | BH18: ='주택총조사(거처의종류, 일반,외국인가구, 아파트)'!O4/'주택총조사(거처의종류, 일반,외국인가구, 전체)'!O4 -> 0.13078471 | BI18: ='주택총조사(거처의종류, 일반,외국인가구, 아파트)'!R4/'주택총조사(거처의종류, 일반,외국인가구, 전체)'!R4 -> 0.11964286 | BJ18: ='주택총조사(거처의종류, 일반,외국인가구, 아파트)'!U4/'주택총조사(거처의종류, 일반,외국인가구, 전체)'!U4 -> 0.11865794 | BK18: ='주택총조사(거처의종류, 일반,외국인가구, 아파트)'!X4/'주택총조사(거처의종류, 일반,외국인가구, 전체)'!X4 -> 0.098582474 | BL18: =BB18*BG18 -> 38.134091 | BM18: =BC18*BH18 -> 14.909457 | BN18: =BD18*BI18 -> 15.075 | BO18: =BE18*BJ18 -> 12.10311 | BP18: =BF18*BK18 -> 32.532216 | BQ18: =AVERAGE(BL18:BP18) -> 22.550775 | BR18: =REPS멸실!E3 -> 0 | BS18: =REPS멸실!F3 -> 0 | BT18: =REPS멸실!G3 -> 0 | BU18: =REPS멸실!H3 -> 0 | BV18: =REPS멸실!I3 -> 0 | BW18: =AVERAGE(BR18:BV18) -> 0 | BX18: =SUM(AU18,BQ18,BW18) -> 791.6763 | BY18: =SUM('주택소유통계(다주택자)'!Q4:R4) -> 10252 | BZ18: =SUM('주택소유통계(다주택자)'!U4:V4) -> 10336 | CA18: =SUM('주택소유통계(다주택자)'!Y4:Z4) -> 10585 | CB18: =SUM('주택소유통계(다주택자)'!AC4:AD4) -> 11082 | CC18: =BZ18-BY18 -> 84 | CD18: =CA18-BZ18 -> 249 | CE18: =CB18-CA18 -> 497 | CF18: ='REPS거래량(외지인)'!D4/'REPS거래량(외지인)'!C4 -> 0.57987867 | CG18: ='REPS거래량(외지인)'!I4/'REPS거래량(외지인)'!H4 -> 0.62726358 | CH18: ='REPS거래량(외지인)'!N4/'REPS거래량(외지인)'!M4 -> 0.67935122 | CI18: =REPS단위당실거래!G3 -> 908.3 | CJ18: =REPS단위당실거래!H3 -> 845.7 | CK18: =REPS단위당실거래!I3 -> 809.4 | CL18: 1461 | CM18: 1671 | CN18: 1498 | CO18: =CI18/CL18 -> 0.62169747 | CP18: =CJ18/CM18 -> 0.50610413 | CQ18: =CK18/CN18 -> 0.54032043 | CR18: 0.2 | CS18: 0.3 | CT18: 0.5 | CU18: =CC18*CF18*CO18*CR18 -> 6.0565528 | CV18: =CD18*CG18*CP18*CS18 -> 23.714313 | CW18: =CE18*CH18*CQ18*CT18 -> 91.216234 | CX18: =AVERAGE(CU18:CW18) -> 40.329033 | CY18: =REPS분양물량!H3 -> 923 | CZ18: =REPS분양물량!I3 -> 1583 | DA18: =REPS분양물량!J3 -> 226 | DB18: =REPS미분양!F3 -> 151 | DC18: =REPS미분양!G3 -> 306 | DD18: =REPS미분양!H3 -> 1139 | DE18: =REPS미분양!I3 -> 1252 | DF18: =SUM(CY18,DB18) -> 1074 | DG18: =SUM(CZ18,DC18) -> 1889 | DH18: =SUM(DA18,DD18) -> 1365 | DI18: =DF18-DC18 -> 768 | DJ18: =DG18-DD18 -> 750 | DK18: =DH18-DE18 -> 113 | DL18: 908.3 | DM18: 845.7 | DN18: 809.4 | DO18: ='REPS분양가(분기단위)'!D3 -> 1461 | DP18: ='REPS분양가(분기단위)'!E3 -> 1671 | DQ18: ='REPS분양가(분기단위)'!F3 -> 1498 | DR18: =DL18/DO18 -> 0.62169747 | DS18: =DM18/DP18 -> 0.50610413 | DT18: =DN18/DQ18 -> 0.54032043 | DU18: =100%-종합!CF18 -> 0.42012133 | DV18: =100%-종합!CG18 -> 0.37273642 | DW18: =100%-종합!CH18 -> 0.32064878 | DX18: 0.2 | DY18: 0.3 | DZ18: 0.5 | EA18: =DI18*DR18*DU18*DX18 -> 40.118534 | EB18: =DJ18*DS18*DV18*DY18 -> 42.444774 | EC18: =DK18*DT18*DW18*DZ18 -> 9.7887995 | ED18: =AVERAGE(EA18:EC18) -> 30.784036 | EE18: =CX18+ED18 -> 71.113069 | EF18: =BX18+EE18 -> 862.78937 | EG18: =REPS단위당실거래!I3 -> 809.4 | EH18: =DQ18 -> 1498 | EI18: =ROUND(EH18*34,-2) -> 50900 | EJ18: =EI18*0.55 -> 27995 | EK18: 13085 | EL18: =FZ18 -> 0.63743408 | EM18: 0.74 | EN18: 0.05 | EO18: =EK18*EL18*EM18*EN18 -> 308.61052 | EP18: =REPS단위당실거래!I3 -> 809.4 | EQ18: =DQ18 -> 1498 | ER18: =ROUND(EQ18*34,-2) -> 50900 | ES18: =ER18*0.55 -> 27995 | ET18: 4067 | EU18: =FZ18 -> 0.63743408 | EV18: 0.26 | EW18: 0.2 | EX18: =ET18*EU18*EV18*EW18 -> 134.80711 | EY18: ='주택총조사(주택의종류)'!AZ4 -> 0.58659237 | EZ18: ='주택총조사(주택의종류)'!AS4 -> 0.34102101 | FA18: ='주택총조사(주택의종류)'!BG4 -> 0.052102984 | FB18: =SUM(EZ18:FA18)/EY18 -> 0.67018259 | FC18: =SUM(EO18,EX18)*FB18 -> 297.17077 | FD18: 0.4 | FE18: 0.6 | FF18: =FC18*FD18*FE18 -> 71.320986 | FG18: =SUM(EO18,EX18,FF18) -> 514.73861 | FH18: 0.0394 | FI18: 30 | FJ18: 0.6 | FK18: 0.4 | FL18: =ROUND(EH18*34,-3) -> 51000 | FM18: =ROUND(EH18*34*FJ18,-2) -> 30600 | FN18: =PMT(FH18/12,FI18*12,FM18) -> -145.03259 | FO18: =-ROUND(FN18/FK18,-1)*12 -> 4320 | FP18: 177 | FQ18: 613 | FR18: 5794 | FS18: 8076 | FT18: 4526 | FU18: 4158 | FV18: 4055 | FW18: 8923 | FX18: 7857 | FY18: =SUM(FP18:FX18) -> 44179 | FZ18: =(SUM(FU18:FX18)/FY18)+(FT18/FY18)*0.7 -> 0.63743408 | GA18: =SUM(AO18,BQ18) -> 778.976 | GB18: 0.3 | GC18: =FZ18 -> 0.63743408 | GD18: =GA18*GB18*GC18 -> 148.96375 | GE18: =SUM(AI18,BW18) -> 12.7003 | GF18: 0.7 | GG18: =FZ18 -> 0.63743408 | GH18: =GE18*GF18*GG18 -> 5.6669228 | GI18: =GD18+GH18 -> 154.63068 | GJ18: =CX18 -> 40.329033 | GK18: =ED18 -> 30.784036 | GL18: =SUM('주택총조사(주택의종류)'!AD4:AF4) -> 58289 | GM18: =REPS미분양!I3 -> 1252 | GN18: =GM18/GL18 -> 0.021479181 | GO18: =LOOKUP(GN18,$GW$25:$GX$28) -> 0.4 | GP18: =SUM(GJ18:GK18)*GO18 -> 28.445228 | GQ18: =SUM(FG18,GI18,GP18) -> 697.81452 | GR18: =SUM('REPS분양물량+계획'!G3:I3)/3 -> 811.66667 | GS18: =GR18/GQ18 -> 1.1631553 | GT18: =LOOKUP(GS18,$GW$16:$GX$20) -> B등급 | GV18: 50%초과~100%이하 | GW18: 0.501 | GX18: A등급
A19: 강원도 | B19: 고성군 | C19: ='주택총조사(거처의종류, 일반,외국인가구, 전체)'!H5 -> 12031 | D19: ='주택총조사(거처의종류, 일반,외국인가구, 전체)'!K5 -> 11132 | E19: ='주택총조사(거처의종류, 일반,외국인가구, 전체)'!N5 -> 11723 | F19: ='주택총조사(거처의종류, 일반,외국인가구, 전체)'!Q5 -> 11992 | G19: ='주택총조사(거처의종류, 일반,외국인가구, 전체)'!T5 -> 12309 | H19: ='주택총조사(거처의종류, 일반,외국인가구, 전체)'!W5 -> 12866 | I19: =D19-C19-T19 -> -36 | J19: =E19-D19-U19 -> 1 | K19: =F19-E19-V19 -> 113 | L19: =G19-F19-W19 -> 131 | M19: =H19-G19-X19 -> -36 | N19: ='인구총조사(가구, 1인가구)'!D5 -> 4686 | O19: ='인구총조사(가구, 1인가구)'!E5 -> 3823 | P19: ='인구총조사(가구, 1인가구)'!F5 -> 4413 | Q19: ='인구총조사(가구, 1인가구)'!G5 -> 4569 | R19: ='인구총조사(가구, 1인가구)'!H5 -> 4755 | S19: ='인구총조사(가구, 1인가구)'!I5 -> 5348 | T19: =O19-N19 -> -863 | U19: =P19-O19 -> 590 | V19: =Q19-P19 -> 156 | W19: =R19-Q19 -> 186 | X19: =S19-R19 -> 593 | Y19: ='주택총조사(거처의종류, 일반,외국인가구, 아파트)'!K5/'주택총조사(거처의종류, 일반,외국인가구, 전체)'!K5 -> 0.13986705 | Z19: ='주택총조사(거처의종류, 일반,외국인가구, 아파트)'!N5/'주택총조사(거처의종류, 일반,외국인가구, 전체)'!N5 -> 0.1389576 | AA19: ='주택총조사(거처의종류, 일반,외국인가구, 아파트)'!Q5/'주택총조사(거처의종류, 일반,외국인가구, 전체)'!Q5 -> 0.18312208 | AB19: ='주택총조사(거처의종류, 일반,외국인가구, 아파트)'!T5/'주택총조사(거처의종류, 일반,외국인가구, 전체)'!T5 -> 0.19660411 | AC19: ='주택총조사(거처의종류, 일반,외국인가구, 아파트)'!W5/'주택총조사(거처의종류, 일반,외국인가구, 전체)'!W5 -> 0.19166796 | AD19: =I19*Y19 -> -5.0352138 | AE19: =J19*Z19 -> 0.1389576 | AF19: =K19*AA19 -> 20.692795 | AG19: =L19*AB19 -> 25.755139 | AH19: =M19*AC19 -> -6.9000466 | AI19: =AVERAGE(AD19:AH19) -> 6.9303262 | AJ19: =T19*Y19 -> -120.70526 | AK19: =U19*Z19 -> 81.984987 | AL19: =V19*AA19 -> 28.567045 | AM19: =W19*AB19 -> 36.568365 | AN19: =X19*AC19 -> 113.6591 | AO19: =AVERAGE(AJ19:AN19) -> 28.014847 | AP19: =AD19+AJ19 -> -125.74048 | AQ19: =AE19+AK19 -> 82.123944 | AR19: =AF19+AL19 -> 49.25984 | AS19: =AG19+AM19 -> 62.323503 | AT19: =AH19+AN19 -> 106.75905 | AU19: =AVERAGE(AP19:AT19) -> 34.945173 | AV19: ='주택총조사(거처의종류, 일반,외국인가구, 전체)'!I5 -> 130 | AW19: ='주택총조사(거처의종류, 일반,외국인가구, 전체)'!L5 -> 142 | AX19: ='주택총조사(거처의종류, 일반,외국인가구, 전체)'!O5 -> 355 | AY19: ='주택총조사(거처의종류, 일반,외국인가구, 전체)'!R5 -> 377 | AZ19: ='주택총조사(거처의종류, 일반,외국인가구, 전체)'!U5 -> 428 | BA19: ='주택총조사(거처의종류, 일반,외국인가구, 전체)'!X5 -> 497 | BB19: =AW19-AV19 -> 12 | BC19: =AX19-AW19 -> 213 | BD19: =AY19-AX19 -> 22 | BE19: =AZ19-AY19 -> 51 | BF19: =BA19-AZ19 -> 69 | BG19: ='주택총조사(거처의종류, 일반,외국인가구, 아파트)'!L5/'주택총조사(거처의종류, 일반,외국인가구, 전체)'!L5 -> 0 | BH19: ='주택총조사(거처의종류, 일반,외국인가구, 아파트)'!O5/'주택총조사(거처의종류, 일반,외국인가구, 전체)'!O5 -> 0 | BI19: ='주택총조사(거처의종류, 일반,외국인가구, 아파트)'!R5/'주택총조사(거처의종류, 일반,외국인가구, 전체)'!R5 -> 0 | BJ19: ='주택총조사(거처의종류, 일반,외국인가구, 아파트)'!U5/'주택총조사(거처의종류, 일반,외국인가구, 전체)'!U5 -> 0.021028037 | BK19: ='주택총조사(거처의종류, 일반,외국인가구, 아파트)'!X5/'주택총조사(거처의종류, 일반,외국인가구, 전체)'!X5 -> 0.018108652 | BL19: =BB19*BG19 -> 0 | BM19: =BC19*BH19 -> 0 | BN19: =BD19*BI19 -> 0 | BO19: =BE19*BJ19 -> 1.0724299 | BP19: =BF19*BK19 -> 1.249497 | BQ19: =AVERAGE(BL19:BP19) -> 0.46438538 | BR19: =REPS멸실!E4 -> 0 | BS19: =REPS멸실!F4 -> 0 | BT19: =REPS멸실!G4 -> 0 | BU19: =REPS멸실!H4 -> 0 | BV19: =REPS멸실!I4 -> 0 | BW19: =AVERAGE(BR19:BV19) -> 0 | BX19: =SUM(AU19,BQ19,BW19) -> 35.409558 | BY19: =SUM('주택소유통계(다주택자)'!Q5:R5) -> 1708 | BZ19: =SUM('주택소유통계(다주택자)'!U5:V5) -> 1838 | CA19: =SUM('주택소유통계(다주택자)'!Y5:Z5) -> 1924 | CB19: =SUM('주택소유통계(다주택자)'!AC5:AD5) -> 2040 | CC19: =BZ19-BY19 -> 130 | CD19: =CA19-BZ19 -> 86 | CE19: =CB19-CA19 -> 116 | CF19: ='REPS거래량(외지인)'!D5/'REPS거래량(외지인)'!C5 -> 0.45631068 | CG19: ='REPS거래량(외지인)'!I5/'REPS거래량(외지인)'!H5 -> 0.44444444 | CH19: ='REPS거래량(외지인)'!N5/'REPS거래량(외지인)'!M5 -> 0.45205479 | CI19: =REPS단위당실거래!G4 -> 803.5 | CJ19: =REPS단위당실거래!H4 -> 755.3 | CK19: =REPS단위당실거래!I4 -> 744.3 | CL19: 1141 | CM19: 1198.05 | CN19: 1257.9525 | CO19: 0 | CP19: =CJ19/CM19 -> 0.63044113 | CQ19: =CK19/CN19 -> 0.59167576 | CR19: 0.2 | CS19: 0.3 | CT19: 0.5 | CU19: 0 | CV19: =CD19*CG19*CP19*CS19 -> 7.2290583 | CW19: =CE19*CH19*CQ19*CT19 -> 15.513252 | CX19: =AVERAGE(CU19:CW19) -> 7.5807701 | CY19: =REPS분양물량!H4 -> 811 | CZ19: =REPS분양물량!I4 -> 100 | DA19: =REPS분양물량!J4 -> 0 | DB19: =REPS미분양!F4 -> 0 | DC19: =REPS미분양!G4 -> 0 | DD19: =REPS미분양!H4 -> 0 | DE19: =REPS미분양!I4 -> 0 | DF19: =SUM(CY19,DB19) -> 811 | DG19: =SUM(CZ19,DC19) -> 100 | DH19: =SUM(DA19,DD19) -> 0 | DI19: =DF19-DC19 -> 811 | DJ19: =DG19-DD19 -> 100 | DK19: =DH19-DE19 -> 0 | DL19: 803.5 | DM19: 755.3 | DN19: 744.3 | DO19: ='REPS분양가(분기단위)'!D4 -> 1141 | DP19: =DO19*1.05 -> 1198.05 | DQ19: =DP19*1.05 -> 1257.9525 | DR19: =DL19/DO19 -> 0.70420684 | DS19: =DM19/DP19 -> 0.63044113 | DT19: =DN19/DQ19 -> 0.59167576 | DU19: =100%-종합!CF19 -> 0.54368932 | DV19: =100%-종합!CG19 -> 0.55555556 | DW19: =100%-종합!CH19 -> 0.54794521 | DX19: 0.2 | DY19: 0.3 | DZ19: 0.5 | EA19: =DI19*DR19*DU19*DX19 -> 62.101471 | EB19: =DJ19*DS19*DV19*DY19 -> 10.507352 | EC19: =DK19*DT19*DW19*DZ19 -> 0 | ED19: =AVERAGE(EA19:EC19) -> 24.202941 | EE19: =CX19+ED19 -> 31.783711 | EF19: =BX19+EE19 -> 67.19327 | EG19: =REPS단위당실거래!I4 -> 744.3 | EH19: =DQ19 -> 1257.9525 | EI19: =ROUND(EH19*34,-2) -> 42800 | EJ19: =EI19*0.55 -> 23540 | EK19: 1458 | EL19: =FZ19 -> 0.72568351 | EM19: 0.74 | EN19: 0.05 | EO19: =EK19*EL19*EM19*EN19 -> 39.147723 | EP19: =REPS단위당실거래!I4 -> 744.3 | EQ19: =DQ19 -> 1257.9525 | ER19: =ROUND(EQ19*34,-2) -> 42800 | ES19: =ER19*0.55 -> 23540 | ET19: 605 | EU19: =FZ19 -> 0.72568351 | EV19: 0.26 | EW19: 0.2 | EX19: =ET19*EU19*EV19*EW19 -> 22.830003 | EY19: ='주택총조사(주택의종류)'!AZ5 -> 0.2207504 | EZ19: ='주택총조사(주택의종류)'!AS5 -> 0.72707627 | FA19: ='주택총조사(주택의종류)'!BG5 -> 0.021706133 | FB19: =SUM(EZ19:FA19)/EY19 -> 3.3919867 | FC19: =SUM(EO19,EX19)*FB19 -> 210.22762 | FD19: 0.4 | FE19: 0.6 | FF19: =FC19*FD19*FE19 -> 50.454629 | FG19: =SUM(EO19,EX19,FF19) -> 112.43235 | FH19: 0.0394 | FI19: 30 | FJ19: 0.6 | FK19: 0.4 | FL19: =ROUND(EH19*34,-3) -> 43000 | FM19: =ROUND(EH19*34*FJ19,-2) -> 25700 | FN19: =PMT(FH19/12,FI19*12,FM19) -> -121.80842 | FO19: =-ROUND(FN19/FK19,-1)*12 -> 3600 | FP19: - | FQ19: 44 | FR19: 281 | FS19: 562 | FT19: 315 | FU19: 245 | FV19: 207 | FW19: 491 | FX19: 269 | FY19: =SUM(FP19:FX19) -> 2414 | FZ19: =(SUM(FT19:FX19)/FY19)+(FS19/FY19)*0.4 -> 0.72568351 | GA19: =SUM(AO19,BQ19) -> 28.479232 | GB19: 0.3 | GC19: =FZ19 -> 0.72568351 | GD19: =GA19*GB19*GC19 -> 6.2000728 | GE19: =SUM(AI19,BW19) -> 6.9303262 | GF19: 0.7 | GG19: =FZ19 -> 0.72568351 | GH19: =GE19*GF19*GG19 -> 3.5204564 | GI19: =GD19+GH19 -> 9.7205292 | GJ19: =CX19 -> 7.5807701 | GK19: =ED19 -> 24.202941 | GL19: =SUM('주택총조사(주택의종류)'!AD5:AF5) -> 3783 | GM19: =REPS미분양!I4 -> 0 | GN19: =GM19/GL19 -> 0 | GO19: =LOOKUP(GN19,$GW$25:$GX$28) -> 1 | GP19: =SUM(GJ19:GK19)*GO19 -> 31.783711 | GQ19: =SUM(FG19,GI19,GP19) -> 153.9366 | GR19: =SUM('REPS분양물량+계획'!G4:I4)/3 -> 0 | GS19: =GR19/GQ19 -> 0 | GT19: =LOOKUP(GS19,$GW$16:$GX$20) -> S등급 | GV19: 100%초과~150%이하 | GW19: 1.001 | GX19: B등급
A20: 강원도 | B20: 동해시 | C20: ='주택총조사(거처의종류, 일반,외국인가구, 전체)'!H6 -> 35984 | D20: ='주택총조사(거처의종류, 일반,외국인가구, 전체)'!K6 -> 36214 | E20: ='주택총조사(거처의종류, 일반,외국인가구, 전체)'!N6 -> 37427 | F20: ='주택총조사(거처의종류, 일반,외국인가구, 전체)'!Q6 -> 38396 | G20: ='주택총조사(거처의종류, 일반,외국인가구, 전체)'!T6 -> 39024 | H20: ='주택총조사(거처의종류, 일반,외국인가구, 전체)'!W6 -> 39492 | I20: =D20-C20-T20 -> 33 | J20: =E20-D20-U20 -> 259 | K20: =F20-E20-V20 -> -48 | L20: =G20-F20-W20 -> -151 | M20: =H20-G20-X20 -> -393 | N20: ='인구총조사(가구, 1인가구)'!D6 -> 10346 | O20: ='인구총조사(가구, 1인가구)'!E6 -> 10543 | P20: ='인구총조사(가구, 1인가구)'!F6 -> 11497 | Q20: ='인구총조사(가구, 1인가구)'!G6 -> 12514 | R20: ='인구총조사(가구, 1인가구)'!H6 -> 13293 | S20: ='인구총조사(가구, 1인가구)'!I6 -> 14154 | T20: =O20-N20 -> 197 | U20: =P20-O20 -> 954 | V20: =Q20-P20 -> 1017 | W20: =R20-Q20 -> 779 | X20: =S20-R20 -> 861 | Y20: ='주택총조사(거처의종류, 일반,외국인가구, 아파트)'!K6/'주택총조사(거처의종류, 일반,외국인가구, 전체)'!K6 -> 0.57767714 | Z20: ='주택총조사(거처의종류, 일반,외국인가구, 아파트)'!N6/'주택총조사(거처의종류, 일반,외국인가구, 전체)'!N6 -> 0.59491811 | AA20: ='주택총조사(거처의종류, 일반,외국인가구, 아파트)'!Q6/'주택총조사(거처의종류, 일반,외국인가구, 전체)'!Q6 -> 0.60498489 | AB20: ='주택총조사(거처의종류, 일반,외국인가구, 아파트)'!T6/'주택총조사(거처의종류, 일반,외국인가구, 전체)'!T6 -> 0.61369926 | AC20: ='주택총조사(거처의종류, 일반,외국인가구, 아파트)'!W6/'주택총조사(거처의종류, 일반,외국인가구, 전체)'!W6 -> 0.61442824 | AD20: =I20*Y20 -> 19.063346 | AE20: =J20*Z20 -> 154.08379 | AF20: =K20*AA20 -> -29.039275 | AG20: =L20*AB20 -> -92.668589 | AH20: =M20*AC20 -> -241.4703 | AI20: =AVERAGE(AD20:AH20) -> -38.006205 | AJ20: =T20*Y20 -> 113.8024 | AK20: =U20*Z20 -> 567.55187 | AL20: =V20*AA20 -> 615.26964 | AM20: =W20*AB20 -> 478.07173 | AN20: =X20*AC20 -> 529.02271 | AO20: =AVERAGE(AJ20:AN20) -> 460.74367 | AP20: =AD20+AJ20 -> 132.86574 | AQ20: =AE20+AK20 -> 721.63566 | AR20: =AF20+AL20 -> 586.23036 | AS20: =AG20+AM20 -> 385.40314 | AT20: =AH20+AN20 -> 287.55242 | AU20: =AVERAGE(AP20:AT20) -> 422.73746 | AV20: ='주택총조사(거처의종류, 일반,외국인가구, 전체)'!I6 -> 349 | AW20: ='주택총조사(거처의종류, 일반,외국인가구, 전체)'!L6 -> 376 | AX20: ='주택총조사(거처의종류, 일반,외국인가구, 전체)'!O6 -> 422 | AY20: ='주택총조사(거처의종류, 일반,외국인가구, 전체)'!R6 -> 289 | AZ20: ='주택총조사(거처의종류, 일반,외국인가구, 전체)'!U6 -> 286 | BA20: ='주택총조사(거처의종류, 일반,외국인가구, 전체)'!X6 -> 338 | BB20: =AW20-AV20 -> 27 | BC20: =AX20-AW20 -> 46 | BD20: =AY20-AX20 -> -133 | BE20: =AZ20-AY20 -> -3 | BF20: =BA20-AZ20 -> 52 | BG20: ='주택총조사(거처의종류, 일반,외국인가구, 아파트)'!L6/'주택총조사(거처의종류, 일반,외국인가구, 전체)'!L6 -> 0.17021277 | BH20: ='주택총조사(거처의종류, 일반,외국인가구, 아파트)'!O6/'주택총조사(거처의종류, 일반,외국인가구, 전체)'!O6 -> 0.14218009 | BI20: ='주택총조사(거처의종류, 일반,외국인가구, 아파트)'!R6/'주택총조사(거처의종류, 일반,외국인가구, 전체)'!R6 -> 0.21799308 | BJ20: ='주택총조사(거처의종류, 일반,외국인가구, 아파트)'!U6/'주택총조사(거처의종류, 일반,외국인가구, 전체)'!U6 -> 0.25174825 | BK20: ='주택총조사(거처의종류, 일반,외국인가구, 아파트)'!X6/'주택총조사(거처의종류, 일반,외국인가구, 전체)'!X6 -> 0.19822485 | BL20: =BB20*BG20 -> 4.5957447 | BM20: =BC20*BH20 -> 6.5402844 | BN20: =BD20*BI20 -> -28.99308 | BO20: =BE20*BJ20 -> -0.75524476 | BP20: =BF20*BK20 -> 10.307692 | BQ20: =AVERAGE(BL20:BP20) -> -1.6609206 | BR20: =REPS멸실!E5 -> 0 | BS20: =REPS멸실!F5 -> 0 | BT20: =REPS멸실!G5 -> 0 | BU20: =REPS멸실!H5 -> 0 | BV20: =REPS멸실!I5 -> 0 | BW20: =AVERAGE(BR20:BV20) -> 0 | BX20: =SUM(AU20,BQ20,BW20) -> 421.07654 | BY20: =SUM('주택소유통계(다주택자)'!Q6:R6) -> 4095 | BZ20: =SUM('주택소유통계(다주택자)'!U6:V6) -> 4066 | CA20: =SUM('주택소유통계(다주택자)'!Y6:Z6) -> 4140 | CB20: =SUM('주택소유통계(다주택자)'!AC6:AD6) -> 4235 | CC20: =BZ20-BY20 -> -29 | CD20: =CA20-BZ20 -> 74 | CE20: =CB20-CA20 -> 95 | CF20: ='REPS거래량(외지인)'!D6/'REPS거래량(외지인)'!C6 -> 0.51776039 | CG20: ='REPS거래량(외지인)'!I6/'REPS거래량(외지인)'!H6 -> 0.44698897 | CH20: ='REPS거래량(외지인)'!N6/'REPS거래량(외지인)'!M6 -> 0.66133109 | CI20: =REPS단위당실거래!G5 -> 558.6 | CJ20: =REPS단위당실거래!H5 -> 558.7 | CK20: =REPS단위당실거래!I5 -> 559.6 | CL20: 0 | CM20: 0 | CN20: 0 | CO20: =CI20/CL20 -> #DIV/0! | CP20: =CJ20/CM20 -> #DIV/0! | CQ20: =CK20/CN20 -> #DIV/0! | CR20: 0.2 | CS20: 0.3 | CT20: 0.5 | CU20: =CC20*CF20*CO20*CR20 -> #DIV/0! | CV20: =CD20*CG20*CP20*CS20 -> #DIV/0! | CW20: =CE20*CH20*CQ20*CT20 -> #DIV/0! | CX20: =AVERAGE(CU20:CW20) -> #DIV/0! | CY20: =REPS분양물량!H5 -> 0 | CZ20: =REPS분양물량!I5 -> 0 | DA20: =REPS분양물량!J5 -> 0 | DB20: =REPS미분양!F5 -> 32 | DC20: =REPS미분양!G5 -> 19 | DD20: =REPS미분양!H5 -> 5 | DE20: =REPS미분양!I5 -> 0 | DF20: =SUM(CY20,DB20) -> 32 | DG20: =SUM(CZ20,DC20) -> 19 | DH20: =SUM(DA20,DD20) -> 5 | DI20: =DF20-DC20 -> 13 | DJ20: =DG20-DD20 -> 14 | DK20: =DH20-DE20 -> 5 | DL20: 558.6 | DM20: 558.7 | DN20: 559.6 | DO20: ='REPS분양가(분기단위)'!D5 -> 0 | DP20: ='REPS분양가(분기단위)'!E5 -> 0 | DQ20: ='REPS분양가(분기단위)'!F5 -> 0 | DR20: =DL20/DO20 -> #DIV/0! | DS20: =DM20/DP20 -> #DIV/0! | DT20: =DN20/DQ20 -> #DIV/0! | DU20: =100%-종합!CF20 -> 0.48223961 | DV20: =100%-종합!CG20 -> 0.55301103 | DW20: =100%-종합!CH20 -> 0.33866891 | DX20: 0.2 | DY20: 0.3 | DZ20: 0.5 | EA20: =DI20*DR20*DU20*DX20 -> #DIV/0! | EB20: =DJ20*DS20*DV20*DY20 -> #DIV/0! | EC20: =DK20*DT20*DW20*DZ20 -> #DIV/0! | ED20: =AVERAGE(EA20:EC20) -> #DIV/0! | EE20: =CX20+ED20 -> #DIV/0! | EF20: =BX20+EE20 -> #DIV/0! | EG20: =REPS단위당실거래!I5 -> 559.6 | EH20: =DQ20 -> 0 | EI20: =ROUND(EH20*34,-2) -> 0 | EJ20: =EI20*0.55 -> 0 | EK20: 0 | EL20: =FZ20 -> 0 | EM20: 0.74 | EN20: 0.05 | EO20: =EK20*EL20*EM20*EN20 -> 0 | EP20: =REPS단위당실거래!I5 -> 559.6 | EQ20: =DQ20 -> 0 | ER20: =ROUND(EQ20*34,-2) -> 0 | ES20: =ER20*0.55 -> 0 | ET20: 0 | EU20: =FZ20 -> 0 | EV20: 0.26 | EW20: 0.2 | EX20: =ET20*EU20*EV20*EW20 -> 0 | EY20: ='주택총조사(주택의종류)'!AZ6 -> 0.65375272 | EZ20: ='주택총조사(주택의종류)'!AS6 -> 0.25967112 | FA20: ='주택총조사(주택의종류)'!BG6 -> 0.06965585 | FB20: =SUM(EZ20:FA20)/EY20 -> 0.50374853 | FC20: =SUM(EO20,EX20)*FB20 -> 0 | FD20: 0.4 | FE20: 0.6 | FF20: =FC20*FD20*FE20 -> 0 | FG20: =SUM(EO20,EX20,FF20) -> 0 | FH20: 0.0394 | FI20: 30 | FJ20: 0.6 | FK20: 0.4 | FL20: =ROUND(EH20*34,-3) -> 0 | FM20: =ROUND(EH20*34*FJ20,-2) -> 0 | FN20: =PMT(FH20/12,FI20*12,FM20) -> 0 | FO20: =-ROUND(FN20/FK20,-1)*12 -> 0 | FP20: 107 | FQ20: 336 | FR20: 2928 | FS20: 4252 | FT20: 2405 | FU20: 2207 | FV20: 2081 | FW20: 4549 | FX20: 3567 | FY20: =SUM(FP20:FX20) -> 22432 | FZ20: 0 | GA20: =SUM(AO20,BQ20) -> 459.08275 | GB20: 0.3 | GC20: =FZ20 -> 0 | GD20: =GA20*GB20*GC20 -> 0 | GE20: =SUM(AI20,BW20) -> -38.006205 | GF20: 0.7 | GG20: =FZ20 -> 0 | GH20: =GE20*GF20*GG20 -> 0 | GI20: =GD20+GH20 -> 0 | GJ20: =CX20 -> #DIV/0! | GK20: =ED20 -> #DIV/0! | GL20: =SUM('주택총조사(주택의종류)'!AD6:AF6) -> 31122 | GM20: =REPS미분양!I5 -> 0 | GN20: =GM20/GL20 -> 0 | GO20: =LOOKUP(GN20,$GW$25:$GX$28) -> 1 | GP20: =SUM(GJ20:GK20)*GO20 -> #DIV/0! | GQ20: =SUM(FG20,GI20,GP20) -> #DIV/0! | GR20: =SUM('REPS분양물량+계획'!G5:I5)/3 -> 0 | GS20: =GR20/GQ20 -> #DIV/0! | GT20: =LOOKUP(GS20,$GW$16:$GX$20) -> #DIV/0! | GV20: 150%초과 | GW20: 1.501 | GX20: C등급
A21: 강원도 | B21: 삼척시 | C21: ='주택총조사(거처의종류, 일반,외국인가구, 전체)'!H7 -> 29470 | D21: ='주택총조사(거처의종류, 일반,외국인가구, 전체)'!K7 -> 29361 | E21: ='주택총조사(거처의종류, 일반,외국인가구, 전체)'!N7 -> 30764 | F21: ='주택총조사(거처의종류, 일반,외국인가구, 전체)'!Q7 -> 29554 | G21: ='주택총조사(거처의종류, 일반,외국인가구, 전체)'!T7 -> 29676 | H21: ='주택총조사(거처의종류, 일반,외국인가구, 전체)'!W7 -> 30225 | I21: =D21-C21-T21 -> -24 | J21: =E21-D21-U21 -> -279 | K21: =F21-E21-V21 -> -389 | L21: =G21-F21-W21 -> -41 | M21: =H21-G21-X21 -> -277 | N21: ='인구총조사(가구, 1인가구)'!D7 -> 10919 | O21: ='인구총조사(가구, 1인가구)'!E7 -> 10834 | P21: ='인구총조사(가구, 1인가구)'!F7 -> 12516 | Q21: ='인구총조사(가구, 1인가구)'!G7 -> 11695 | R21: ='인구총조사(가구, 1인가구)'!H7 -> 11858 | S21: ='인구총조사(가구, 1인가구)'!I7 -> 12684 | T21: =O21-N21 -> -85 | U21: =P21-O21 -> 1682 | V21: =Q21-P21 -> -821 | W21: =R21-Q21 -> 163 | X21: =S21-R21 -> 826 | Y21: ='주택총조사(거처의종류, 일반,외국인가구, 아파트)'!K7/'주택총조사(거처의종류, 일반,외국인가구, 전체)'!K7 -> 0.39709138 | Z21: ='주택총조사(거처의종류, 일반,외국인가구, 아파트)'!N7/'주택총조사(거처의종류, 일반,외국인가구, 전체)'!N7 -> 0.37937199 | AA21: ='주택총조사(거처의종류, 일반,외국인가구, 아파트)'!Q7/'주택총조사(거처의종류, 일반,외국인가구, 전체)'!Q7 -> 0.39669757 | AB21: ='주택총조사(거처의종류, 일반,외국인가구, 아파트)'!T7/'주택총조사(거처의종류, 일반,외국인가구, 전체)'!T7 -> 0.4137687 | AC21: ='주택총조사(거처의종류, 일반,외국인가구, 아파트)'!W7/'주택총조사(거처의종류, 일반,외국인가구, 전체)'!W7 -> 0.40899917 | AD21: =I21*Y21 -> -9.5301931 | AE21: =J21*Z21 -> -105.84479 | AF21: =K21*AA21 -> -154.31535 | AG21: =L21*AB21 -> -16.964517 | AH21: =M21*AC21 -> -113.29277 | AI21: =AVERAGE(AD21:AH21) -> -79.989524 | AJ21: =T21*Y21 -> -33.752767 | AK21: =U21*Z21 -> 638.10369 | AL21: =V21*AA21 -> -325.68871 | AM21: =W21*AB21 -> 67.444298 | AN21: =X21*AC21 -> 337.83332 | AO21: =AVERAGE(AJ21:AN21) -> 136.78797 | AP21: =AD21+AJ21 -> -43.28296 | AQ21: =AE21+AK21 -> 532.25891 | AR21: =AF21+AL21 -> -480.00406 | AS21: =AG21+AM21 -> 50.479782 | AT21: =AH21+AN21 -> 224.54055 | AU21: =AVERAGE(AP21:AT21) -> 56.798443 | AV21: ='주택총조사(거처의종류, 일반,외국인가구, 전체)'!I7 -> 208 | AW21: ='주택총조사(거처의종류, 일반,외국인가구, 전체)'!L7 -> 219 | AX21: ='주택총조사(거처의종류, 일반,외국인가구, 전체)'!O7 -> 224 | AY21: ='주택총조사(거처의종류, 일반,외국인가구, 전체)'!R7 -> 223 | AZ21: ='주택총조사(거처의종류, 일반,외국인가구, 전체)'!U7 -> 243 | BA21: ='주택총조사(거처의종류, 일반,외국인가구, 전체)'!X7 -> 296 | BB21: =AW21-AV21 -> 11 | BC21: =AX21-AW21 -> 5 | BD21: =AY21-AX21 -> -1 | BE21: =AZ21-AY21 -> 20 | BF21: =BA21-AZ21 -> 53 | BG21: ='주택총조사(거처의종류, 일반,외국인가구, 아파트)'!L7/'주택총조사(거처의종류, 일반,외국인가구, 전체)'!L7 -> 0.21004566 | BH21: ='주택총조사(거처의종류, 일반,외국인가구, 아파트)'!O7/'주택총조사(거처의종류, 일반,외국인가구, 전체)'!O7 -> 0.20089286 | BI21: ='주택총조사(거처의종류, 일반,외국인가구, 아파트)'!R7/'주택총조사(거처의종류, 일반,외국인가구, 전체)'!R7 -> 0.16591928 | BJ21: ='주택총조사(거처의종류, 일반,외국인가구, 아파트)'!U7/'주택총조사(거처의종류, 일반,외국인가구, 전체)'!U7 -> 0.18930041 | BK21: ='주택총조사(거처의종류, 일반,외국인가구, 아파트)'!X7/'주택총조사(거처의종류, 일반,외국인가구, 전체)'!X7 -> 0.15202703 | BL21: =BB21*BG21 -> 2.3105023 | BM21: =BC21*BH21 -> 1.0044643 | BN21: =BD21*BI21 -> -0.16591928 | BO21: =BE21*BJ21 -> 3.7860082 | BP21: =BF21*BK21 -> 8.0574324 | BQ21: =AVERAGE(BL21:BP21) -> 2.9984976 | BR21: =REPS멸실!E6 -> 0 | BS21: =REPS멸실!F6 -> 0 | BT21: =REPS멸실!G6 -> 0 | BU21: =REPS멸실!H6 -> 0 | BV21: =REPS멸실!I6 -> 42 | BW21: =AVERAGE(BR21:BV21) -> 8.4 | BX21: =SUM(AU21,BQ21,BW21) -> 68.19694 | BY21: =SUM('주택소유통계(다주택자)'!Q7:R7) -> 3439 | BZ21: =SUM('주택소유통계(다주택자)'!U7:V7) -> 3444 | CA21: =SUM('주택소유통계(다주택자)'!Y7:Z7) -> 3631 | CB21: =SUM('주택소유통계(다주택자)'!AC7:AD7) -> 3835 | CC21: =BZ21-BY21 -> 5 | CD21: =CA21-BZ21 -> 187 | CE21: =CB21-CA21 -> 204 | CF21: ='REPS거래량(외지인)'!D7/'REPS거래량(외지인)'!C7 -> 0.67039106 | CG21: ='REPS거래량(외지인)'!I7/'REPS거래량(외지인)'!H7 -> 0.72134595 | CH21: ='REPS거래량(외지인)'!N7/'REPS거래량(외지인)'!M7 -> 0.69811321 | CI21: =REPS단위당실거래!G6 -> 491.2 | CJ21: =REPS단위당실거래!H6 -> 529.4 | CK21: =REPS단위당실거래!I6 -> 548.4 | CL21: 0 | CM21: 0 | CN21: 0 | CO21: =CI21/CL21 -> #DIV/0! | CP21: =CJ21/CM21 -> #DIV/0! | CQ21: =CK21/CN21 -> #DIV/0! | CR21: 0.2 | CS21: 0.3 | CT21: 0.5 | CU21: =CC21*CF21*CO21*CR21 -> #DIV/0! | CV21: =CD21*CG21*CP21*CS21 -> #DIV/0! | CW21: =CE21*CH21*CQ21*CT21 -> #DIV/0! | CX21: =AVERAGE(CU21:CW21) -> #DIV/0! | CY21: =REPS분양물량!H6 -> 0 | CZ21: =REPS분양물량!I6 -> 0 | DA21: =REPS분양물량!J6 -> 0 | DB21: =REPS미분양!F6 -> 99 | DC21: =REPS미분양!G6 -> 61 | DD21: =REPS미분양!H6 -> 40 | DE21: =REPS미분양!I6 -> 78 | DF21: =SUM(CY21,DB21) -> 99 | DG21: =SUM(CZ21,DC21) -> 61 | DH21: =SUM(DA21,DD21) -> 40 | DI21: =DF21-DC21 -> 38 | DJ21: =DG21-DD21 -> 21 | DK21: =DH21-DE21 -> -38 | DL21: 491.2 | DM21: 529.4 | DN21: 548.4 | DO21: ='REPS분양가(분기단위)'!D6 -> 0 | DP21: ='REPS분양가(분기단위)'!E6 -> 0 | DQ21: ='REPS분양가(분기단위)'!F6 -> 0 | DR21: =DL21/DO21 -> #DIV/0! | DS21: =DM21/DP21 -> #DIV/0! | DT21: =DN21/DQ21 -> #DIV/0! | DU21: =100%-종합!CF21 -> 0.32960894 | DV21: =100%-종합!CG21 -> 0.27865405 | DW21: =100%-종합!CH21 -> 0.30188679 | DX21: 0.2 | DY21: 0.3 | DZ21: 0.5 | EA21: =DI21*DR21*DU21*DX21 -> #DIV/0! | EB21: =DJ21*DS21*DV21*DY21 -> #DIV/0! | EC21: =DK21*DT21*DW21*DZ21 -> #DIV/0! | ED21: =AVERAGE(EA21:EC21) -> #DIV/0! | EE21: =CX21+ED21 -> #DIV/0! | EF21: =BX21+EE21 -> #DIV/0! | EG21: =REPS단위당실거래!I6 -> 548.4 | EH21: =DQ21 -> 0 | EI21: =ROUND(EH21*34,-2) -> 0 | EJ21: =EI21*0.55 -> 0 | EK21: 0 | EL21: =FZ21 -> 0 | EM21: 0.74 | EN21: 0.05 | EO21: =EK21*EL21*EM21*EN21 -> 0 | EP21: =REPS단위당실거래!I6 -> 548.4 | EQ21: =DQ21 -> 0 | ER21: =ROUND(EQ21*34,-2) -> 0 | ES21: =ER21*0.55 -> 0 | ET21: 0 | EU21: =FZ21 -> 0 | EV21: 0.26 | EW21: 0.2 | EX21: =ET21*EU21*EV21*EW21 -> 0 | EY21: ='주택총조사(주택의종류)'!AZ7 -> 0.4674501 | EZ21: ='주택총조사(주택의종류)'!AS7 -> 0.43260975 | FA21: ='주택총조사(주택의종류)'!BG7 -> 0.081174384 | FB21: =SUM(EZ21:FA21)/EY21 -> 1.0991208 | FC21: =SUM(EO21,EX21)*FB21 -> 0 | FD21: 0.4 | FE21: 0.6 | FF21: =FC21*FD21*FE21 -> 0 | FG21: =SUM(EO21,EX21,FF21) -> 0 | FH21: 0.0394 | FI21: 30 | FJ21: 0.6 | FK21: 0.4 | FL21: =ROUND(EH21*34,-3) -> 0 | FM21: =ROUND(EH21*34*FJ21,-2) -> 0 | FN21: =PMT(FH21/12,FI21*12,FM21) -> 0 | FO21: =-ROUND(FN21/FK21,-1)*12 -> 0 | FP21: 58 | FQ21: 170 | FR21: 1592 | FS21: 2266 | FT21: 1334 | FU21: 1150 | FV21: 1006 | FW21: 2279 | FX21: 1839 | FY21: =SUM(FP21:FX21) -> 11694 | FZ21: 0 | GA21: =SUM(AO21,BQ21) -> 139.78646 | GB21: 0.3 | GC21: =FZ21 -> 0 | GD21: =GA21*GB21*GC21 -> 0 | GE21: =SUM(AI21,BW21) -> -71.589524 | GF21: 0.7 | GG21: =FZ21 -> 0 | GH21: =GE21*GF21*GG21 -> 0 | GI21: =GD21+GH21 -> 0 | GJ21: =CX21 -> #DIV/0! | GK21: =ED21 -> #DIV/0! | GL21: =SUM('주택총조사(주택의종류)'!AD7:AF7) -> 17685 | GM21: =REPS미분양!I6 -> 78 | GN21: =GM21/GL21 -> 0.0044105174 | GO21: =LOOKUP(GN21,$GW$25:$GX$28) -> 1 | GP21: =SUM(GJ21:GK21)*GO21 -> #DIV/0! | GQ21: =SUM(FG21,GI21,GP21) -> #DIV/0! | GR21: =SUM('REPS분양물량+계획'!G6:I6)/3 -> 139.33333 | GS21: =GR21/GQ21 -> #DIV/0! | GT21: =LOOKUP(GS21,$GW$16:$GX$20) -> #DIV/0!
A22: 강원도 | B22: 속초시 | C22: ='주택총조사(거처의종류, 일반,외국인가구, 전체)'!H8 -> 33623 | D22: ='주택총조사(거처의종류, 일반,외국인가구, 전체)'!K8 -> 34213 | E22: ='주택총조사(거처의종류, 일반,외국인가구, 전체)'!N8 -> 35551 | F22: ='주택총조사(거처의종류, 일반,외국인가구, 전체)'!Q8 -> 36656 | G22: ='주택총조사(거처의종류, 일반,외국인가구, 전체)'!T8 -> 37502 | H22: ='주택총조사(거처의종류, 일반,외국인가구, 전체)'!W8 -> 38042 | I22: =D22-C22-T22 -> 283 | J22: =E22-D22-U22 -> 327 | K22: =F22-E22-V22 -> -43 | L22: =G22-F22-W22 -> 86 | M22: =H22-G22-X22 -> -188 | N22: ='인구총조사(가구, 1인가구)'!D8 -> 10804 | O22: ='인구총조사(가구, 1인가구)'!E8 -> 11111 | P22: ='인구총조사(가구, 1인가구)'!F8 -> 12122 | Q22: ='인구총조사(가구, 1인가구)'!G8 -> 13270 | R22: ='인구총조사(가구, 1인가구)'!H8 -> 14030 | S22: ='인구총조사(가구, 1인가구)'!I8 -> 14758 | T22: =O22-N22 -> 307 | U22: =P22-O22 -> 1011 | V22: =Q22-P22 -> 1148 | W22: =R22-Q22 -> 760 | X22: =S22-R22 -> 728 | Y22: ='주택총조사(거처의종류, 일반,외국인가구, 아파트)'!K8/'주택총조사(거처의종류, 일반,외국인가구, 전체)'!K8 -> 0.61111273 | Z22: ='주택총조사(거처의종류, 일반,외국인가구, 아파트)'!N8/'주택총조사(거처의종류, 일반,외국인가구, 전체)'!N8 -> 0.62484881 | AA22: ='주택총조사(거처의종류, 일반,외국인가구, 아파트)'!Q8/'주택총조사(거처의종류, 일반,외국인가구, 전체)'!Q8 -> 0.63454823 | AB22: ='주택총조사(거처의종류, 일반,외국인가구, 아파트)'!T8/'주택총조사(거처의종류, 일반,외국인가구, 전체)'!T8 -> 0.6425524 | AC22: ='주택총조사(거처의종류, 일반,외국인가구, 아파트)'!W8/'주택총조사(거처의종류, 일반,외국인가구, 전체)'!W8 -> 0.64583881 | AD22: =I22*Y22 -> 172.9449 | AE22: =J22*Z22 -> 204.32556 | AF22: =K22*AA22 -> -27.285574 | AG22: =L22*AB22 -> 55.259506 | AH22: =M22*AC22 -> -121.4177 | AI22: =AVERAGE(AD22:AH22) -> 56.76534 | AJ22: =T22*Y22 -> 187.61161 | AK22: =U22*Z22 -> 631.72215 | AL22: =V22*AA22 -> 728.46137 | AM22: =W22*AB22 -> 488.33982 | AN22: =X22*AC22 -> 470.17065 | AO22: =AVERAGE(AJ22:AN22) -> 501.26112 | AP22: =AD22+AJ22 -> 360.55651 | AQ22: =AE22+AK22 -> 836.04771 | AR22: =AF22+AL22 -> 701.1758 | AS22: =AG22+AM22 -> 543.59933 | AT22: =AH22+AN22 -> 348.75296 | AU22: =AVERAGE(AP22:AT22) -> 558.02646 | AV22: ='주택총조사(거처의종류, 일반,외국인가구, 전체)'!I8 -> 310 | AW22: ='주택총조사(거처의종류, 일반,외국인가구, 전체)'!L8 -> 318 | AX22: ='주택총조사(거처의종류, 일반,외국인가구, 전체)'!O8 -> 352 | AY22: ='주택총조사(거처의종류, 일반,외국인가구, 전체)'!R8 -> 387 | AZ22: ='주택총조사(거처의종류, 일반,외국인가구, 전체)'!U8 -> 397 | BA22: ='주택총조사(거처의종류, 일반,외국인가구, 전체)'!X8 -> 479 | BB22: =AW22-AV22 -> 8 | BC22: =AX22-AW22 -> 34 | BD22: =AY22-AX22 -> 35 | BE22: =AZ22-AY22 -> 10 | BF22: =BA22-AZ22 -> 82 | BG22: ='주택총조사(거처의종류, 일반,외국인가구, 아파트)'!L8/'주택총조사(거처의종류, 일반,외국인가구, 전체)'!L8 -> 0.28301887 | BH22: ='주택총조사(거처의종류, 일반,외국인가구, 아파트)'!O8/'주택총조사(거처의종류, 일반,외국인가구, 전체)'!O8 -> 0.31534091 | BI22: ='주택총조사(거처의종류, 일반,외국인가구, 아파트)'!R8/'주택총조사(거처의종류, 일반,외국인가구, 전체)'!R8 -> 0.32041344 | BJ22: ='주택총조사(거처의종류, 일반,외국인가구, 아파트)'!U8/'주택총조사(거처의종류, 일반,외국인가구, 전체)'!U8 -> 0.29219144 | BK22: ='주택총조사(거처의종류, 일반,외국인가구, 아파트)'!X8/'주택총조사(거처의종류, 일반,외국인가구, 전체)'!X8 -> 0.2526096 | BL22: =BB22*BG22 -> 2.2641509 | BM22: =BC22*BH22 -> 10.721591 | BN22: =BD22*BI22 -> 11.21447 | BO22: =BE22*BJ22 -> 2.9219144 | BP22: =BF22*BK22 -> 20.713987 | BQ22: =AVERAGE(BL22:BP22) -> 9.5672228 | BR22: =REPS멸실!E7 -> 0 | BS22: =REPS멸실!F7 -> 0 | BT22: =REPS멸실!G7 -> 0 | BU22: =REPS멸실!H7 -> 0 | BV22: =REPS멸실!I7 -> 0 | BW22: =AVERAGE(BR22:BV22) -> 0 | BX22: =SUM(AU22,BQ22,BW22) -> 567.59368 | BY22: =SUM('주택소유통계(다주택자)'!Q8:R8) -> 4483 | BZ22: =SUM('주택소유통계(다주택자)'!U8:V8) -> 4571 | CA22: =SUM('주택소유통계(다주택자)'!Y8:Z8) -> 4689 | CB22: =SUM('주택소유통계(다주택자)'!AC8:AD8) -> 4884 | CC22: =BZ22-BY22 -> 88 | CD22: =CA22-BZ22 -> 118 | CE22: =CB22-CA22 -> 195 | CF22: ='REPS거래량(외지인)'!D8/'REPS거래량(외지인)'!C8 -> 0.46763636 | CG22: ='REPS거래량(외지인)'!I8/'REPS거래량(외지인)'!H8 -> 0.50248756 | CH22: ='REPS거래량(외지인)'!N8/'REPS거래량(외지인)'!M8 -> 0.59981768 | CI22: =REPS단위당실거래!G7 -> 862.8 | CJ22: =REPS단위당실거래!H7 -> 842.4 | CK22: =REPS단위당실거래!I7 -> 834.4 | CL22: 1542 | CM22: 1679 | CN22: 1762.95 | CO22: =CI22/CL22 -> 0.55953307 | CP22: =CJ22/CM22 -> 0.50172722 | CQ22: =CK22/CN22 -> 0.4732976 | CR22: 0.2 | CS22: 0.3 | CT22: 0.5 | CU22: =CC22*CF22*CO22*CR22 -> 4.605181 | CV22: =CD22*CG22*CP22*CS22 -> 8.9247537 | CW22: =CE22*CH22*CQ22*CT22 -> 27.679496 | CX22: =AVERAGE(CU22:CW22) -> 13.736477 | CY22: =REPS분양물량!H7 -> 228 | CZ22: =REPS분양물량!I7 -> 925 | DA22: =REPS분양물량!J7 -> 0 | DB22: =REPS미분양!F7 -> 112 | DC22: =REPS미분양!G7 -> 170 | DD22: =REPS미분양!H7 -> 686 | DE22: =REPS미분양!I7 -> 1019 | DF22: =SUM(CY22,DB22) -> 340 | DG22: =SUM(CZ22,DC22) -> 1095 | DH22: =SUM(DA22,DD22) -> 686 | DI22: =DF22-DC22 -> 170 | DJ22: =DG22-DD22 -> 409 | DK22: =DH22-DE22 -> -333 | DL22: 862.8 | DM22: 842.4 | DN22: 834.4 | DO22: ='REPS분양가(분기단위)'!D7 -> 1542 | DP22: ='REPS분양가(분기단위)'!E7 -> 1679 | DQ22: =DP22*1.05 -> 1762.95 | DR22: =DL22/DO22 -> 0.55953307 | DS22: =DM22/DP22 -> 0.50172722 | DT22: =DN22/DQ22 -> 0.4732976 | DU22: =100%-종합!CF22 -> 0.53236364 | DV22: =100%-종합!CG22 -> 0.49751244 | DW22: =100%-종합!CH22 -> 0.40018232 | DX22: 0.2 | DY22: 0.3 | DZ22: 0.5 | EA22: =DI22*DR22*DU22*DX22 -> 10.127752 | EB22: =DJ22*DS22*DV22*DY22 -> 30.627826 | EC22: =DK22*DT22*DW22*DZ22 -> -31.535987 | ED22: =AVERAGE(EA22:EC22) -> 3.0731969 | EE22: =CX22+ED22 -> 16.809674 | EF22: =BX22+EE22 -> 584.40336 | EG22: =REPS단위당실거래!I7 -> 834.4 | EH22: =DQ22 -> 1762.95 | EI22: =ROUND(EH22*34,-2) -> 59900 | EJ22: =EI22*0.55 -> 32945 | EK22: 6785 | EL22: =FZ22 -> 0.50190854 | EM22: 0.74 | EN22: 0.05 | EO22: =EK22*EL22*EM22*EN22 -> 126.00163 | EP22: =REPS단위당실거래!I7 -> 834.4 | EQ22: =DQ22 -> 1762.95 | ER22: =ROUND(EQ22*34,-2) -> 59900 | ES22: =ER22*0.55 -> 32945 | ET22: 110 | EU22: =FZ22 -> 0.50190854 | EV22: 0.26 | EW22: 0.2 | EX22: =ET22*EU22*EV22*EW22 -> 2.8709169 | EY22: ='주택총조사(주택의종류)'!AZ8 -> 0.6999691 | EZ22: ='주택총조사(주택의종류)'!AS8 -> 0.22704555 | FA22: ='주택총조사(주택의종류)'!BG8 -> 0.056433181 | FB22: =SUM(EZ22:FA22)/EY22 -> 0.40498749 | FC22: =SUM(EO22,EX22)*FB22 -> 52.191769 | FD22: 0.4 | FE22: 0.6 | FF22: =FC22*FD22*FE22 -> 12.526025 | FG22: =SUM(EO22,EX22,FF22) -> 141.39857 | FH22: 0.0394 | FI22: 30 | FJ22: 0.6 | FK22: 0.4 | FL22: =ROUND(EH22*34,-3) -> 60000 | FM22: =ROUND(EH22*34*FJ22,-2) -> 36000 | FN22: =PMT(FH22/12,FI22*12,FM22) -> -170.62657 | FO22: =-ROUND(FN22/FK22,-1)*12 -> 5160 | FP22: 84 | FQ22: 337 | FR22: 3025 | FS22: 4320 | FT22: 2371 | FU22: 2033 | FV22: 1904 | FW22: 4097 | FX22: 2997 | FY22: =SUM(FP22:FX22) -> 21168 | FZ22: =(SUM(FV22:FX22)/FY22)+(FU22/FY22)*0.8 -> 0.50190854 | GA22: =SUM(AO22,BQ22) -> 510.82834 | GB22: 0.3 | GC22: =FZ22 -> 0.50190854 | GD22: =GA22*GB22*GC22 -> 76.916733 | GE22: =SUM(AI22,BW22) -> 56.76534 | GF22: 0.7 | GG22: =FZ22 -> 0.50190854 | GH22: =GE22*GF22*GG22 -> 19.943706 | GI22: =GD22+GH22 -> 96.860439 | GJ22: =CX22 -> 13.736477 | GK22: =ED22 -> 3.0731969 | GL22: =SUM('주택총조사(주택의종류)'!AD8:AF8) -> 30693 | GM22: =REPS미분양!I7 -> 1019 | GN22: =GM22/GL22 -> 0.033199752 | GO22: =LOOKUP(GN22,$GW$25:$GX$28) -> 0.4 | GP22: =SUM(GJ22:GK22)*GO22 -> 6.7238695 | GQ22: =SUM(FG22,GI22,GP22) -> 244.98288 | GR22: =SUM('REPS분양물량+계획'!G7:I7)/3 -> 649.66667 | GS22: =GR22/GQ22 -> 2.651886 | GT22: =LOOKUP(GS22,$GW$16:$GX$20) -> C등급
A23: 강원도 | B23: 양구군 | C23: ='주택총조사(거처의종류, 일반,외국인가구, 전체)'!H9 -> 9076 | D23: ='주택총조사(거처의종류, 일반,외국인가구, 전체)'!K9 -> 8519 | E23: ='주택총조사(거처의종류, 일반,외국인가구, 전체)'!N9 -> 8521 | F23: ='주택총조사(거처의종류, 일반,외국인가구, 전체)'!Q9 -> 8733 | G23: ='주택총조사(거처의종류, 일반,외국인가구, 전체)'!T9 -> 8822 | H23: ='주택총조사(거처의종류, 일반,외국인가구, 전체)'!W9 -> 9027 | I23: =D23-C23-T23 -> 17 | J23: =E23-D23-U23 -> 8 | K23: =F23-E23-V23 -> -46 | L23: =G23-F23-W23 -> -119 | M23: =H23-G23-X23 -> -65 | N23: ='인구총조사(가구, 1인가구)'!D9 -> 3111 | O23: ='인구총조사(가구, 1인가구)'!E9 -> 2537 | P23: ='인구총조사(가구, 1인가구)'!F9 -> 2531 | Q23: ='인구총조사(가구, 1인가구)'!G9 -> 2789 | R23: ='인구총조사(가구, 1인가구)'!H9 -> 2997 | S23: ='인구총조사(가구, 1인가구)'!I9 -> 3267 | T23: =O23-N23 -> -574 | U23: =P23-O23 -> -6 | V23: =Q23-P23 -> 258 | W23: =R23-Q23 -> 208 | X23: =S23-R23 -> 270 | Y23: ='주택총조사(거처의종류, 일반,외국인가구, 아파트)'!K9/'주택총조사(거처의종류, 일반,외국인가구, 전체)'!K9 -> 0.27585397 | Z23: ='주택총조사(거처의종류, 일반,외국인가구, 아파트)'!N9/'주택총조사(거처의종류, 일반,외국인가구, 전체)'!N9 -> 0.27144701 | AA23: ='주택총조사(거처의종류, 일반,외국인가구, 아파트)'!Q9/'주택총조사(거처의종류, 일반,외국인가구, 전체)'!Q9 -> 0.26806367 | AB23: ='주택총조사(거처의종류, 일반,외국인가구, 아파트)'!T9/'주택총조사(거처의종류, 일반,외국인가구, 전체)'!T9 -> 0.26932668 | AC23: ='주택총조사(거처의종류, 일반,외국인가구, 아파트)'!W9/'주택총조사(거처의종류, 일반,외국인가구, 전체)'!W9 -> 0.26154869 | AD23: =I23*Y23 -> 4.6895175 | AE23: =J23*Z23 -> 2.1715761 | AF23: =K23*AA23 -> -12.330929 | AG23: =L23*AB23 -> -32.049875 | AH23: =M23*AC23 -> -17.000665 | AI23: =AVERAGE(AD23:AH23) -> -10.904075 | AJ23: =T23*Y23 -> -158.34018 | AK23: =U23*Z23 -> -1.6286821 | AL23: =V23*AA23 -> 69.160426 | AM23: =W23*AB23 -> 56.01995 | AN23: =X23*AC23 -> 70.618146 | AO23: =AVERAGE(AJ23:AN23) -> 7.1659318 | AP23: =AD23+AJ23 -> -153.65066 | AQ23: =AE23+AK23 -> 0.54289403 | AR23: =AF23+AL23 -> 56.829497 | AS23: =AG23+AM23 -> 23.970075 | AT23: =AH23+AN23 -> 53.617481 | AU23: =AVERAGE(AP23:AT23) -> -3.7381432 | AV23: ='주택총조사(거처의종류, 일반,외국인가구, 전체)'!I9 -> 74 | AW23: ='주택총조사(거처의종류, 일반,외국인가구, 전체)'!L9 -> 81 | AX23: ='주택총조사(거처의종류, 일반,외국인가구, 전체)'!O9 -> 77 | AY23: ='주택총조사(거처의종류, 일반,외국인가구, 전체)'!R9 -> 108 | AZ23: ='주택총조사(거처의종류, 일반,외국인가구, 전체)'!U9 -> 125 | BA23: ='주택총조사(거처의종류, 일반,외국인가구, 전체)'!X9 -> 231 | BB23: =AW23-AV23 -> 7 | BC23: =AX23-AW23 -> -4 | BD23: =AY23-AX23 -> 31 | BE23: =AZ23-AY23 -> 17 | BF23: =BA23-AZ23 -> 106 | BG23: ='주택총조사(거처의종류, 일반,외국인가구, 아파트)'!L9/'주택총조사(거처의종류, 일반,외국인가구, 전체)'!L9 -> 0.12345679 | BH23: ='주택총조사(거처의종류, 일반,외국인가구, 아파트)'!O9/'주택총조사(거처의종류, 일반,외국인가구, 전체)'!O9 -> 0.077922078 | BI23: ='주택총조사(거처의종류, 일반,외국인가구, 아파트)'!R9/'주택총조사(거처의종류, 일반,외국인가구, 전체)'!R9 -> 0.14814815 | BJ23: ='주택총조사(거처의종류, 일반,외국인가구, 아파트)'!U9/'주택총조사(거처의종류, 일반,외국인가구, 전체)'!U9 -> 0.168 | BK23: ='주택총조사(거처의종류, 일반,외국인가구, 아파트)'!X9/'주택총조사(거처의종류, 일반,외국인가구, 전체)'!X9 -> 0.073593074 | BL23: =BB23*BG23 -> 0.86419753 | BM23: =BC23*BH23 -> -0.31168831 | BN23: =BD23*BI23 -> 4.5925926 | BO23: =BE23*BJ23 -> 2.856 | BP23: =BF23*BK23 -> 7.8008658 | BQ23: =AVERAGE(BL23:BP23) -> 3.1603935 | BR23: =REPS멸실!E8 -> 0 | BS23: =REPS멸실!F8 -> 0 | BT23: =REPS멸실!G8 -> 0 | BU23: =REPS멸실!H8 -> 0 | BV23: =REPS멸실!I8 -> 0 | BW23: =AVERAGE(BR23:BV23) -> 0 | BX23: =SUM(AU23,BQ23,BW23) -> -0.57774971 | BY23: =SUM('주택소유통계(다주택자)'!Q9:R9) -> 868 | BZ23: =SUM('주택소유통계(다주택자)'!U9:V9) -> 951 | CA23: =SUM('주택소유통계(다주택자)'!Y9:Z9) -> 987 | CB23: =SUM('주택소유통계(다주택자)'!AC9:AD9) -> 1036 | CC23: =BZ23-BY23 -> 83 | CD23: =CA23-BZ23 -> 36 | CE23: =CB23-CA23 -> 49 | CF23: ='REPS거래량(외지인)'!D9/'REPS거래량(외지인)'!C9 -> 0.92391304 | CG23: ='REPS거래량(외지인)'!I9/'REPS거래량(외지인)'!H9 -> 0.9125 | CH23: ='REPS거래량(외지인)'!N9/'REPS거래량(외지인)'!M9 -> 0.74117647 | CI23: =REPS단위당실거래!G8 -> 539.2 | CJ23: =REPS단위당실거래!H8 -> 544.1 | CK23: =REPS단위당실거래!I8 -> 570 | CL23: 0 | CM23: 0 | CN23: 0 | CO23: 0 | CP23: 0 | CQ23: 0 | CR23: 0.2 | CS23: 0.3 | CT23: 0.5 | CU23: =CC23*CF23*CO23*CR23 -> 0 | CV23: =CD23*CG23*CP23*CS23 -> 0 | CW23: =CE23*CH23*CQ23*CT23 -> 0 | CX23: =AVERAGE(CU23:CW23) -> 0 | CY23: =REPS분양물량!H8 -> 0 | CZ23: =REPS분양물량!I8 -> 0 | DA23: =REPS분양물량!J8 -> 100 | DB23: =REPS미분양!F8 -> 0 | DC23: =REPS미분양!G8 -> 0 | DD23: =REPS미분양!H8 -> 0 | DE23: =REPS미분양!I8 -> 0 | DF23: =SUM(CY23,DB23) -> 0 | DG23: =SUM(CZ23,DC23) -> 0 | DH23: =SUM(DA23,DD23) -> 100 | DI23: =DF23-DC23 -> 0 | DJ23: =DG23-DD23 -> 0 | DK23: =DH23-DE23 -> 100 | DL23: 539.2 | DM23: 544.1 | DN23: 570 | DO23: ='REPS분양가(분기단위)'!D8 -> 0 | DP23: ='REPS분양가(분기단위)'!E8 -> 0 | DQ23: ='REPS분양가(분기단위)'!F8 -> 0 | DR23: =DL23/DO23 -> #DIV/0! | DS23: =DM23/DP23 -> #DIV/0! | DT23: =DN23/DQ23 -> #DIV/0! | DU23: =100%-종합!CF23 -> 0.076086957 | DV23: =100%-종합!CG23 -> 0.0875 | DW23: =100%-종합!CH23 -> 0.25882353 | DX23: 0.2 | DY23: 0.3 | DZ23: 0.5 | EA23: =DI23*DR23*DU23*DX23 -> #DIV/0! | EB23: =DJ23*DS23*DV23*DY23 -> #DIV/0! | EC23: =DK23*DT23*DW23*DZ23 -> #DIV/0! | ED23: =AVERAGE(EA23:EC23) -> #DIV/0! | EE23: =CX23+ED23 -> #DIV/0! | EF23: =BX23+EE23 -> #DIV/0! | EG23: =REPS단위당실거래!I8 -> 570 | EH23: =DQ23 -> 0 | EI23: =ROUND(EH23*34,-2) -> 0 | EJ23: =EI23*0.55 -> 0 | EK23: 0 | EL23: =FZ23 -> 0 | EM23: 0.74 | EN23: 0.05 | EO23: =EK23*EL23*EM23*EN23 -> 0 | EP23: =REPS단위당실거래!I8 -> 570 | EQ23: =DQ23 -> 0 | ER23: =ROUND(EQ23*34,-2) -> 0 | ES23: =ER23*0.55 -> 0 | ET23: 0 | EU23: =FZ23 -> 0 | EV23: 0.26 | EW23: 0.2 | EX23: =ET23*EU23*EV23*EW23 -> 0 | EY23: ='주택총조사(주택의종류)'!AZ9 -> 0.323692 | EZ23: ='주택총조사(주택의종류)'!AS9 -> 0.58335421 | FA23: ='주택총조사(주택의종류)'!BG9 -> 0.061489273 | FB23: =SUM(EZ23:FA23)/EY23 -> 1.9921514 | FC23: =SUM(EO23,EX23)*FB23 -> 0 | FD23: 0.4 | FE23: 0.6 | FF23: =FC23*FD23*FE23 -> 0 | FG23: =SUM(EO23,EX23,FF23) -> 0 | FH23: 0.0394 | FI23: 30 | FJ23: 0.6 | FK23: 0.4 | FL23: =ROUND(EH23*34,-3) -> 0 | FM23: =ROUND(EH23*34*FJ23,-2) -> 0 | FN23: =PMT(FH23/12,FI23*12,FM23) -> 0 | FO23: =-ROUND(FN23/FK23,-1)*12 -> 0 | FP23: - | FQ23: 41 | FR23: 231 | FS23: 486 | FT23: 241 | FU23: 213 | FV23: 200 | FW23: 474 | FX23: 298 | FY23: =SUM(FP23:FX23) -> 2184 | FZ23: 0 | GA23: =SUM(AO23,BQ23) -> 10.326325 | GB23: 0.3 | GC23: =FZ23 -> 0 | GD23: =GA23*GB23*GC23 -> 0 | GE23: =SUM(AI23,BW23) -> -10.904075 | GF23: 0.7 | GG23: =FZ23 -> 0 | GH23: =GE23*GF23*GG23 -> 0 | GI23: =GD23+GH23 -> 0 | GJ23: =CX23 -> 0 | GK23: =ED23 -> #DIV/0! | GL23: =SUM('주택총조사(주택의종류)'!AD9:AF9) -> 3192 | GM23: =REPS미분양!I8 -> 0 | GN23: =GM23/GL23 -> 0 | GO23: =LOOKUP(GN23,$GW$25:$GX$28) -> 1 | GP23: =SUM(GJ23:GK23)*GO23 -> #DIV/0! | GQ23: =SUM(FG23,GI23,GP23) -> #DIV/0! | GR23: =SUM('REPS분양물량+계획'!G8:I8)/3 -> 0 | GS23: =GR23/GQ23 -> #DIV/0! | GT23: =LOOKUP(GS23,$GW$16:$GX$20) -> #DIV/0!
